Workbook
Name ActivatedExperts: 'Parameters'!$D$21
Name ActiveHashLayers: 'Parameters'!$D$52
Name BF16Bytes: 'Parameters'!$D$33
Name DC_ExpertActiveProbability: 'Decode_1M'!$B$9
Name DC_IndexPairs: 'Decode_1M'!$B$8
Name DC_LongPairs: 'Decode_1M'!$B$7
Name DC_RawPairs: 'Decode_1M'!$B$5
Name DC_Rows: 'Decode_1M'!$B$4
Name DC_ShortPairs: 'Decode_1M'!$B$6
Name DecodeBatch: 'Parameters'!$D$8
Name DecodeContext: 'Parameters'!$D$10
Name DecodeTargetMs: 'Parameters'!$D$47
Name DecodeTokens: 'Parameters'!$D$9
Name ExpertInter: 'Parameters'!$D$23
Name FP32Bytes: 'Parameters'!$D$34
Name FP4Block: 'Parameters'!$D$41
Name FP4Bytes: 'Parameters'!$D$36
Name FP8Block: 'Parameters'!$D$40
Name FP8Bytes: 'Parameters'!$D$35
Name HashLayers: 'Parameters'!$D$32
Name HBMBandwidthGBps: 'Parameters'!$D$44
Name HCIters: 'Parameters'!$D$31
Name HCSlots: 'Parameters'!$D$30
Name HeadDim: 'Parameters'!$D$15
Name HiddenSize: 'Parameters'!$D$12
Name IndexHeadDim: 'Parameters'!$D$28
Name IndexHeads: 'Parameters'!$D$27
Name IndexTopK: 'Parameters'!$D$29
Name INT32Bytes: 'Parameters'!$D$38
Name INT64Bytes: 'Parameters'!$D$39
Name InterconnectGBps: 'Parameters'!$D$45
Name KernelMinHeads: 'Parameters'!$D$42
Name LongLayers: 'Parameters'!$D$51
Name LongRatio: 'Parameters'!$D$26
Name MaxContext: 'Parameters'!$D$11
Name NumHeads: 'Parameters'!$D$14
Name OGroups: 'Parameters'!$D$18
Name OLoraRank: 'Parameters'!$D$19
Name PeakTFLOPs: 'Parameters'!$D$43
Name PF_ExpertActiveProbability: 'Prefill_8K'!$B$9
Name PF_IndexPairs: 'Prefill_8K'!$B$8
Name PF_LongPairs: 'Prefill_8K'!$B$7
Name PF_RawPairs: 'Prefill_8K'!$B$5
Name PF_Rows: 'Prefill_8K'!$B$4
Name PF_ShortPairs: 'Prefill_8K'!$B$6
Name PrefillBatch: 'Parameters'!$D$6
Name PrefillSequence: 'Parameters'!$D$7
Name PrefillTargetMs: 'Parameters'!$D$46
Name QLoraRank: 'Parameters'!$D$17
Name RopeDim: 'Parameters'!$D$16
Name RoutedExperts: 'Parameters'!$D$20
Name ScaleBytes: 'Parameters'!$D$37
Name SharedExperts: 'Parameters'!$D$22
Name ShortLayers: 'Parameters'!$D$50
Name ShortRatio: 'Parameters'!$D$25
Name TotalLayers: 'Parameters'!$D$48
Name TP1KernelLocalHeads: 'Parameters'!$D$54
Name TP1LocalExperts: 'Parameters'!$D$56
Name TP1LocalHeads: 'Parameters'!$D$53
Name TP1LocalIndexHeads: 'Parameters'!$D$55

Sheet Parameters
A1: DeepSeek V4 Flash - Editable Architecture Parameters
A2: 蓝色单元格为可编辑输入，绿色单元格为 Excel 派生公式。
A3: Category | B3: Parameter | C3: Excel name | D3: Value | E3: Description
A4: Parallel | B4: TP1 comparison size | C4: TP1Size | D4: 1 | E4: 第一组张量并行配置。
A5: Parallel | B5: TP8 comparison size | C5: TP8Size | D5: 8 | E5: 第二组张量并行配置，可编辑。
A6: Scenario | B6: Prefill batch size | C6: PrefillBatch | D6: 1 | E6: 可编辑的预填充批大小。
A7: Scenario | B7: Prefill sequence length | C7: PrefillSequence | D7: 8192 | E7: 一次预填充处理的提示词令牌数。
A8: Scenario | B8: Decode batch size | C8: DecodeBatch | D8: 1 | E8: 可编辑的解码批大小。
A9: Scenario | B9: Decode tokens per step | C9: DecodeTokens | D9: 1 | E9: 通常为 1；公式按解码上下文长度建模每个令牌。
A10: Scenario | B10: Decode context | C10: DecodeContext | D10: 1048576 | E10: 解码阶段可见的有效上下文长度。
A11: Scenario | B11: Maximum allocated context | C11: MaxContext | D11: 1048576 | E11: KV 缓存的预分配容量。
A12: Model | B12: Hidden size | C12: HiddenSize | D12: 4096 | E12: Transformer 残差宽度。
A13: Model | B13: Vocabulary size | C13: VocabSize | D13: 129280 | E13: Embedding 与 LM Head 使用的词表大小。
A14: Attention | B14: Query heads | C14: NumHeads | D14: 64 | E14: 全局 Query 头数量。
A15: Attention | B15: Head dimension | C15: HeadDim | D15: 512 | E15: 共享潜在 KV 宽度及每个 Query 头的宽度。
... A47: Hardware | B47: Decode target latency | C47: DecodeTargetMs | D47: 10 | E47: 仅用于推导所需 HBM 带宽和卡间互连带宽。
A48: Derived | B48: Active layers | C48: TotalLayers | D48: =SUM(Layer_Config!$B$4:$B$67) -> 43 | E48: Layer_Config 中启用的层数。
A49: Derived | B49: Window-only layers | C49: WindowLayers | D49: =COUNTIFS(Layer_Config!$B$4:$B$67,1,Layer_Config!$C$4:$C$67,"window") -> 2 | E49: 启用的窗口模式层数。
A50: Derived | B50: Short-compression layers | C50: ShortLayers | D50: =COUNTIFS(Layer_Config!$B$4:$B$67,1,Layer_Config!$C$4:$C$67,"short") -> 21 | E50: 启用的 ratio-4/短压缩层数。
A51: Derived | B51: Long-compression layers | C51: LongLayers | D51: =COUNTIFS(Layer_Config!$B$4:$B$67,1,Layer_Config!$C$4:$C$67,"long") -> 20 | E51: 启用的 ratio-128/长压缩层数。
A52: Derived | B52: Active hash layers | C52: ActiveHashLayers | D52: =COUNTIFS(Layer_Config!$B$4:$B$67,1,Layer_Config!$A$4:$A$67,"<"&HashLayers) -> 3 | E52: 层 ID 小于 HashLayers 且已启用的层数。
A53: Derived | B53: TP1 local Q heads | C53: TP1LocalHeads | D53: =NumHeads/TP1Size -> 64 | E53: 单个 TP1 Rank 上的 Q 头数。
A54: Derived | B54: TP1 kernel local heads | C54: TP1KernelLocalHeads | D54: =MAX(TP1LocalHeads,KernelMinHeads) -> 64 | E54: 补齐后的稀疏内核本地头数。
A55: Derived | B55: TP1 local index heads | C55: TP1LocalIndexHeads | D55: =IndexHeads/TP1Size -> 64 | E55: 单个 TP1 Rank 上的 Indexer 头数。
A56: Derived | B56: TP1 local experts | C56: TP1LocalExperts | D56: =RoutedExperts/TP1Size -> 256 | E56: 单个 TP1 Rank 上的路由专家数。
A57: Derived | B57: TP1 local output groups | C57: TP1LocalOGroups | D57: =OGroups/TP1Size -> 8 | E57: 单个 TP1 Rank 上的输出分组数。
A58: Derived | B58: TP1 local vocabulary | C58: TP1LocalVocab | D58: =VocabSize/TP1Size -> 129280 | E58: 单个 TP1 Rank 上的词表行数。
A59: Derived | B59: TP8 local Q heads | C59: TP8LocalHeads | D59: =NumHeads/TP8Size -> 8 | E59: 单个 TP8 Rank 上的 Q 头数。
A60: Derived | B60: TP8 kernel local heads | C60: TP8KernelLocalHeads | D60: =MAX(TP8LocalHeads,KernelMinHeads) -> 16 | E60: 补齐后的稀疏内核本地头数。
A61: Derived | B61: TP8 local index heads | C61: TP8LocalIndexHeads | D61: =IndexHeads/TP8Size -> 8 | E61: 单个 TP8 Rank 上的 Indexer 头数。
A62: Derived | B62: TP8 local experts | C62: TP8LocalExperts | D62: =RoutedExperts/TP8Size -> 32 | E62: 单个 TP8 Rank 上的路由专家数。
A63: Derived | B63: TP8 local output groups | C63: TP8LocalOGroups | D63: =OGroups/TP8Size -> 1 | E63: 单个 TP8 Rank 上的输出分组数。
A64: Derived | B64: TP8 local vocabulary | C64: TP8LocalVocab | D64: =VocabSize/TP8Size -> 16160 | E64: 单个 TP8 Rank 上的词表行数。

Sheet Prefill_8K
A1: 8K Prefill - TP1 vs TP8 inference resources
A2: 容量为单 Rank 资源；分类容量是静态参数，整网容量另含 MaxContext 预分配 KV/State。可见通信列为原始集合通信数据量，HBM 读写量保留在隐藏审计列。
A3: Helper metric | B3: Value | C3: Unit | D3: Description
A4: 令牌行数 | B4: =PrefillBatch*PrefillSequence -> 8192 | C4: 令牌行 | D4: 当前场景需要处理的令牌总数；预填充为批大小乘序列长度，解码为批大小乘每步令牌数。
A5: 因果原始窗口对数 | B5: =IF(PrefillSequence<=WindowSize,PrefillSequence*(PrefillSequence+1)/2,WindowSize*(WindowSize+1)/2+(PrefillSequence-WindowSize)*WindowSize) -> 1040448 | C5: 对数/序列 | D5: 因果原始窗口路径中可参与注意力计算的令牌对数量，按每个序列统计。
A6: 封顶短压缩对数 | B6: =IF(PrefillSequence<IndexTopK*ShortRatio,ShortRatio*INT(PrefillSequence/ShortRatio)*(INT(PrefillSequence/ShortRatio)-1)/2+INT(PrefillSequence/ShortRatio)*(MOD(PrefillSequence,ShortRatio)+1),ShortRatio*IndexTopK*(IndexTopK-1)/2+(PrefillSequence-IndexTopK*ShortRatio+1)*IndexTopK) -> 3669504 | C6: 对数/序列 | D6: 短压缩路径的候选令牌对数量；按短压缩比例折叠，并受 Top-K 候选上限约束。
A7: 长压缩对数 | B7: =LongRatio*INT(PrefillSequence/LongRatio)*(INT(PrefillSequence/LongRatio)-1)/2+INT(PrefillSequence/LongRatio)*(MOD(PrefillSequence,LongRatio)+1) -> 258112 | C7: 对数/序列 | D7: 长压缩路径按长压缩比例折叠后的候选令牌对数量。
A8: Indexer 扫描对数 | B8: =ShortRatio*INT(PrefillSequence/ShortRatio)*(INT(PrefillSequence/ShortRatio)-1)/2+INT(PrefillSequence/ShortRatio)*(MOD(PrefillSequence,ShortRatio)+1) -> 8386560 | C8: 对数/序列 | D8: ratio-4 Indexer 评分时需要扫描的压缩条目数量，作为索引器计算量输入。
A9: 专家激活概率 | B9: =1-(1-ActivatedExperts/RoutedExperts)^PF_Rows -> 1 | C9: 概率 | D9: 在当前场景令牌数下，单个路由专家至少被激活一次的概率，用于估算路由专家参数读取量。
A11: 整网与主要模块汇总
A12: 类别 | B12: TP1 容量 | C12: TP1 算力 | D12: TP1 集合通信数据量 | E12: TP8 容量/rank | F12: TP8 算力/rank | G12: TP8 集合通信数据量/rank | H12: 参数类型 | I12: 激活类型 | J12: 说明
A13: 整网 | B13: =TEXT(IF(ABS(AE13)>=1E12,AE13/1E12,IF(ABS(AE13)>=1E9,AE13/1E9,IF(ABS(AE13)>=1E6,AE13/1E6,IF(ABS(AE13)>=1E3,AE13/1E3,AE13)))),"#,##0.000")&IF((IF(ABS(AE13)>=1E12,"TB",IF(ABS(AE13)>=1E9,"GB",IF(ABS(AE13)>=1E6,"MB",IF(ABS(AE13)>=1E3,"KB","bytes")))))="",""," "&(IF(ABS(AE13)>=1E12,"TB",IF(ABS(AE13)>=1E9,"GB",IF(ABS(AE13)>=1E6,"MB",IF(ABS(AE13)>=1E3,"KB","bytes")))))) -> 166.349 GB | C13: =TEXT(IF(ABS(AF13)>=1E15,AF13/1E15,IF(ABS(AF13)>=1E12,AF13/1E12,IF(ABS(AF13)>=1E9,AF13/1E9,IF(ABS(AF13)>=1E6,AF13/1E6,AF13)))),"#,##0.000")&IF((IF(ABS(AF13)>=1E15,"PFLOPs",IF(ABS(AF13)>=1E12,"TFLOPs",IF(ABS(AF13)>=1E9,"GFLOPs",IF(ABS(AF13)>=1E6,"MFLOPs","flops")))))="",""," "&(IF(ABS(AF13)>=1E15,"PFLOPs",IF(ABS(AF13)>=1E12,"TFLOPs",IF(ABS(AF13)>=1E9,"GFLOPs",IF(ABS(AF13)>=1E6,"MFLOPs","flops")))))) -> 228.398 TFLOPs | D13: =TEXT(IF(ABS(AK13)>=1E12,AK13/1E12,IF(ABS(AK13)>=1E9,AK13/1E9,IF(ABS(AK13)>=1E6,AK13/1E6,IF(ABS(AK13)>=1E3,AK13/1E3,AK13)))),"#,##0.000")&IF((IF(ABS(AK13)>=1E12,"TB",IF(ABS(AK13)>=1E9,"GB",IF(ABS(AK13)>=1E6,"MB",IF(ABS(AK13)>=1E3,"KB","bytes")))))="",""," "&(IF(ABS(AK13)>=1E12,"TB",IF(ABS(AK13)>=1E9,"GB",IF(ABS(AK13)>=1E6,"MB",IF(ABS(AK13)>=1E3,"KB","bytes")))))) -> 0.000 B | E13: =TEXT(IF(ABS(AH13)>=1E12,AH13/1E12,IF(ABS(AH13)>=1E9,AH13/1E9,IF(ABS(AH13)>=1E6,AH13/1E6,IF(ABS(AH13)>=1E3,AH13/1E3,AH13)))),"#,##0.000")&IF((IF(ABS(AH13)>=1E12,"TB",IF(ABS(AH13)>=1E9,"GB",IF(ABS(AH13)>=1E6,"MB",IF(ABS(AH13)>=1E3,"KB","bytes")))))="",""," "&(IF(ABS(AH13)>=1E12,"TB",IF(ABS(AH13)>=1E9,"GB",IF(ABS(AH13)>=1E6,"MB",IF(ABS(AH13)>=1E3,"KB","bytes")))))) -> 29.582 GB | F13: =TEXT(IF(ABS(AI13)>=1E15,AI13/1E15,IF(ABS(AI13)>=1E12,AI13/1E12,IF(ABS(AI13)>=1E9,AI13/1E9,IF(ABS(AI13)>=1E6,AI13/1E6,AI13)))),"#,##0.000")&IF((IF(ABS(AI13)>=1E15,"PFLOPs",IF(ABS(AI13)>=1E12,"TFLOPs",IF(ABS(AI13)>=1E9,"GFLOPs",IF(ABS(AI13)>=1E6,"MFLOPs","flops")))))="",""," "&(IF(ABS(AI13)>=1E15,"PFLOPs",IF(ABS(AI13)>=1E12,"TFLOPs",IF(ABS(AI13)>=1E9,"GFLOPs",IF(ABS(AI13)>=1E6,"MFLOPs","flops")))))) -> 55.653 TFLOPs | G13: =TEXT(IF(ABS(AL13)>=1E12,AL13/1E12,IF(ABS(AL13)>=1E9,AL13/1E9,IF(ABS(AL13)>=1E6,AL13/1E6,IF(ABS(AL13)>=1E3,AL13/1E3,AL13)))),"#,##0.000")&IF((IF(ABS(AL13)>=1E12,"TB",IF(ABS(AL13)>=1E9,"GB",IF(ABS(AL13)>=1E6,"MB",IF(ABS(AL13)>=1E3,"KB","bytes")))))="",""," "&(IF(ABS(AL13)>=1E12,"TB",IF(ABS(AL13)>=1E9,"GB",IF(ABS(AL13)>=1E6,"MB",IF(ABS(AL13)>=1E3,"KB","bytes")))))) -> 40.635 GB | H13: FP8 / FP4 / BF16 / FP32 | I13: BF16 / FP32 / INT32 | J13: 全推理路径；容量含 MaxContext KV/State；整网容量 = 静态参数 + 预分配 KV/State。 | AE13: =((TP1LocalVocab*HiddenSize*BF16Bytes)+(TotalLayers*(((HiddenSize)*(QLoraRank)*FP8Bytes+ROUNDUP((HiddenSize)/FP8Block,0)*ROUNDUP((QLoraRank)/FP8Block,0)*ScaleBytes)+((QLoraRank)*(TP1LocalHeads*HeadDim)*FP8Bytes+ROUNDUP((QLoraRank)/FP8Block,0)*ROUNDUP((TP1LocalHeads*HeadDim)/FP8Block,0)*ScaleBytes)+((HiddenSize)*(HeadDim)*FP8Bytes+ROUNDUP((HiddenSize)/FP8Block,0)*ROUNDUP((HeadDim)/FP8Block,0)*ScaleBytes)+TP1LocalHeads*HeadDim*OLoraRank*BF16Bytes+((TP1LocalOGroups*OLoraRank)*(HiddenSize)*FP8Bytes+ROUNDUP((TP1LocalOGroups*OLoraRank)/FP8Block,0)*ROUNDUP((HiddenSize)/FP8Block,0)*ScaleBytes)))+(0)+(0)+(0)+(ShortLayers*(((QLoraRank)*(TP1LocalIndexHeads*IndexHeadDim)*FP8Bytes+ROUNDUP((QLoraRank)/FP8Block,0)*ROUNDUP((TP1LocalIndexHeads*IndexHeadDim)/FP8Block,0)*ScaleBytes)+HiddenSize*TP1LocalIndexHeads*BF16Bytes))+(0)+(ShortLayers*(2*HiddenSize*(2*HeadDim)*FP32Bytes+ShortRatio*2*HeadDim*FP32Bytes+HeadDim*FP32Bytes))+(LongLayers*(2*HiddenSize*HeadDim*FP32Bytes+LongRatio*HeadDim*FP32Bytes+HeadDim*FP32Bytes))+(ShortLayers*(2*HiddenSize*(2*IndexHeadDim)*FP32Bytes+ShortRatio*2*IndexHeadDim*FP32Bytes+IndexHeadDim*FP32Bytes))+(TotalLayers*RoutedExperts*HiddenSize*BF16Bytes+(TotalLayers-ActiveHashLayers)*RoutedExperts*FP32Bytes+ActiveHashLayers*VocabSize*ActivatedExperts*INT32Bytes)+(TotalLayers*TP1LocalExperts*(3*HiddenSize*ExpertInter*FP4Bytes+3*HiddenSize*ExpertInter/FP4Block*ScaleBytes))+(TotalLayers*SharedExperts*(2*((HiddenSize)*(ExpertInter)*FP8Bytes+ROUNDUP((HiddenSize)/FP8Block,0)*ROUNDUP((ExpertInter)/FP8Block,0)*ScaleBytes)+((ExpertInter)*(HiddenSize)*FP8Bytes+ROUNDUP((ExpertInter)/FP8Block,0)*ROUNDUP((HiddenSize)/FP8Block,0)*ScaleBytes)))+((TotalLayers*2*(((2+HCSlots)*HCSlots)*HCSlots*HiddenSize+((2+HCSlots)*HCSlots)+3))*FP32Bytes+(HCSlots*HCSlots*HiddenSize+HCSlots+1)*FP32Bytes)+((TotalLayers*(2*HiddenSize+QLoraRank+HeadDim+TP1LocalHeads))*FP32Bytes+(HiddenSize)*FP32Bytes)+(0)+(TP1LocalVocab*HiddenSize*FP32Bytes)+(0)+(0))+(PrefillBatch*(HeadDim*BF16Bytes*(WindowLayers*WindowSize+ShortLayers*(WindowSize+INT(MaxContext/ShortRatio))+LongLayers*(WindowSize+INT(MaxContext/LongRatio)))+ShortLayers*INT(MaxContext/ShortRatio)*IndexHeadDim*BF16Bytes)+PrefillBatch*FP32Bytes*(ShortLayers*2*(2*ShortRatio)*(2*HeadDim)+LongLayers*2*LongRatio*HeadDim+ShortLayers*2*(2*ShortRatio)*(2*IndexHeadDim))) -> 166349315548 | AF13: =(0)+(PF_Rows*TotalLayers*2*(HiddenSize*QLoraRank+QLoraRank*TP1LocalHeads*HeadDim+HiddenSize*HeadDim+TP1LocalHeads*HeadDim*OLoraRank+TP1LocalOGroups*OLoraRank*HiddenSize))+(4*PrefillBatch*TP1KernelLocalHeads*HeadDim*(WindowLayers*PF_RawPairs))+(4*PrefillBatch*TP1KernelLocalHeads*HeadDim*(ShortLayers*(PF_RawPairs+PF_ShortPairs)))+(4*PrefillBatch*TP1KernelLocalHeads*HeadDim*(LongLayers*(PF_RawPairs+PF_LongPairs)))+(2*PF_Rows*ShortLayers*(QLoraRank*TP1LocalIndexHeads*IndexHeadDim+HiddenSize*TP1LocalIndexHeads))+(2*PrefillBatch*ShortLayers*TP1LocalIndexHeads*IndexHeadDim*PF_IndexPairs)+(PF_Rows*ShortLayers*8*HiddenSize*HeadDim)+(PF_Rows*LongLayers*4*HiddenSize*HeadDim)+(PF_Rows*ShortLayers*8*HiddenSize*IndexHeadDim)+(2*PF_Rows*TotalLayers*HiddenSize*RoutedExperts)+(PF_Rows*TotalLayers*(ActivatedExperts/TP1Size)*6*HiddenSize*ExpertInter)+(PF_Rows*TotalLayers*SharedExperts*6*HiddenSize*ExpertInter)+(TotalLayers*2*(2*PF_Rows*HCSlots*HiddenSize*((2+HCSlots)*HCSlots)+PF_Rows*(2*HCSlots*HiddenSize+1)+PF_Rows*HiddenSize*(2*HCSlots-1)+PF_Rows*HCSlots*HiddenSize*(2*HCSlots+1))+2*PF_Rows*HCSlots*HiddenSize*HCSlots+PF_Rows*(2*HCSlots*HiddenSize+1)+PF_Rows*HiddenSize*(2*HCSlots-1))+(PF_Rows*TotalLayers*2*(4*HiddenSize+1)+PF_Rows*(4*HiddenSize+1))+(0)+(2*PrefillBatch*HiddenSize*TP1LocalVocab)+(0)+(0) -> 228397682114560 | AG13: =((PF_Rows*HiddenSize*BF16Bytes)+(PF_Rows*HiddenSize*BF16Bytes))+((TotalLayers*(((HiddenSize)*(QLoraRank)*FP8Bytes+ROUNDUP((HiddenSize)/FP8Block,0)*ROUNDUP((QLoraRank)/FP8Block,0)*ScaleBytes)+((QLoraRank)*(TP1LocalHeads*HeadDim)*FP8Bytes+ROUNDUP((QLoraRank)/FP8Block,0)*ROUNDUP((TP1LocalHeads*HeadDim)/FP8Block,0)*ScaleBytes)+((HiddenSize)*(HeadDim)*FP8Bytes+ROUNDUP((HiddenSize)/FP8Block,0)*ROUNDUP((HeadDim)/FP8Block,0)*ScaleBytes)+TP1LocalHeads*HeadDim*OLoraRank*BF16Bytes+((TP1LocalOGroups*OLoraRank)*(HiddenSize)*FP8Bytes+ROUNDUP((TP1LocalOGroups*OLoraRank)/FP8Block,0)*ROUNDUP((HiddenSize)/FP8Block,0)*ScaleBytes))+PF_Rows*TotalLayers*(2*HiddenSize*BF16Bytes+QLoraRank*BF16Bytes+TP1KernelLocalHeads*HeadDim*BF16Bytes+TP1LocalOGroups*OLoraRank*BF16Bytes))+(PF_Rows*TotalLayers*(QLoraRank+TP1KernelLocalHeads*HeadDim+HeadDim+TP1LocalOGroups*OLoraRank+HiddenSize)*BF16Bytes))+((PF_Rows*WindowLayers*TP1KernelLocalHeads*HeadDim*BF16Bytes+PrefillBatch*(WindowLayers*PF_RawPairs)*HeadDim*BF16Bytes)+(PF_Rows*WindowLayers*TP1KernelLocalHeads*HeadDim*BF16Bytes))+((PF_Rows*ShortLayers*TP1KernelLocalHeads*HeadDim*BF16Bytes+PrefillBatch*(ShortLayers*(PF_RawPairs+PF_ShortPairs))*HeadDim*BF16Bytes)+(PF_Rows*ShortLayers*TP1KernelLocalHeads*HeadDim*BF16Bytes))+((PF_Rows*LongLayers*TP1KernelLocalHeads*HeadDim*BF16Bytes+PrefillBatch*(LongLayers*(PF_RawPairs+PF_LongPairs))*HeadDim*BF16Bytes)+(PF_Rows*LongLayers*TP1KernelLocalHeads*HeadDim*BF16Bytes))+((ShortLayers*(((QLoraRank)*(TP1LocalIndexHeads*IndexHeadDim)*FP8Bytes+ROUNDUP((QLoraRank)/FP8Block,0)*ROUNDUP((TP1LocalIndexHeads*IndexHeadDim)/FP8Block,0)*ScaleBytes)+HiddenSize*TP1LocalIndexHeads*BF16Bytes)+PF_Rows*ShortLayers*(QLoraRank+HiddenSize)*BF16Bytes)+(PF_Rows*ShortLayers*TP1LocalIndexHeads*(IndexHeadDim+1)*BF16Bytes))+((PrefillBatch*ShortLayers*PF_IndexPairs*(IndexHeadDim*BF16Bytes+TP1LocalIndexHeads*BF16Bytes))+(PrefillBatch*ShortLayers*PF_IndexPairs*(TP1LocalIndexHeads*BF16Bytes+FP32Bytes)))+((ShortLayers*(2*HiddenSize*(2*HeadDim)*FP32Bytes+ShortRatio*2*HeadDim*FP32Bytes+HeadDim*FP32Bytes)+PF_Rows*ShortLayers*HiddenSize*FP32Bytes)+(PF_Rows*ShortLayers*4*HeadDim*FP32Bytes))+((LongLayers*(2*HiddenSize*HeadDim*FP32Bytes+LongRatio*HeadDim*FP32Bytes+HeadDim*FP32Bytes)+PF_Rows*LongLayers*HiddenSize*FP32Bytes)+(PF_Rows*LongLayers*2*HeadDim*FP32Bytes))+((ShortLayers*(2*HiddenSize*(2*IndexHeadDim)*FP32Bytes+ShortRatio*2*IndexHeadDim*FP32Bytes+IndexHeadDim*FP32Bytes)+PF_Rows*ShortLayers*HiddenSize*FP32Bytes)+(PF_Rows*ShortLayers*4*IndexHeadDim*FP32Bytes))+((TotalLayers*RoutedExperts*HiddenSize*BF16Bytes+(TotalLayers-ActiveHashLayers)*RoutedExperts*FP32Bytes+PF_Rows*TotalLayers*HiddenSize*BF16Bytes+PF_Rows*ActiveHashLayers*ActivatedExperts*INT32Bytes)+(PF_Rows*TotalLayers*RoutedExperts*FP32Bytes))+((TotalLayers*TP1LocalExperts*PF_ExpertActiveProbability*(3*HiddenSize*ExpertInter*FP4Bytes+3*HiddenSize*ExpertInter/FP4Block*ScaleBytes)+PF_Rows*TotalLayers*(ActivatedExperts/TP1Size)*HiddenSize*BF16Bytes)+(PF_Rows*TotalLayers*(ActivatedExperts/TP1Size)*HiddenSize*BF16Bytes))+((TotalLayers*SharedExperts*(2*((HiddenSize)*(ExpertInter)*FP8Bytes+ROUNDUP((HiddenSize)/FP8Block,0)*ROUNDUP((ExpertInter)/FP8Block,0)*ScaleBytes)+((ExpertInter)*(HiddenSize)*FP8Bytes+ROUNDUP((ExpertInter)/FP8Block,0)*ROUNDUP((HiddenSize)/FP8Block,0)*ScaleBytes))+PF_Rows*TotalLayers*SharedExperts*HiddenSize*BF16Bytes)+(PF_Rows*TotalLayers*SharedExperts*HiddenSize*BF16Bytes))+((TotalLayers*2*((2+HCSlots)*HCSlots*HCSlots*HiddenSize*FP32Bytes+((2+HCSlots)*HCSlots+3)*FP32Bytes)+PF_Rows*TotalLayers*4*HCSlots*HiddenSize*BF16Bytes+(HCSlots*HCSlots*HiddenSize+HCSlots+1)*FP32Bytes+PF_Rows*HCSlots*HiddenSize*BF16Bytes)+(PF_Rows*TotalLayers*4*HCSlots*HiddenSize*BF16Bytes+PF_Rows*HiddenSize*BF16Bytes))+((TotalLayers*(2*HiddenSize+QLoraRank+HeadDim+TP1LocalHeads)*FP32Bytes+HiddenSize*FP32Bytes+PF_Rows*TotalLayers*2*HiddenSize*BF16Bytes+PF_Rows*HiddenSize*BF16Bytes)+(PF_Rows*TotalLayers*2*HiddenSize*BF16Bytes+PF_Rows*HiddenSize*BF16Bytes))+((0)+(0))+((TP1LocalVocab*HiddenSize*FP32Bytes+PrefillBatch*HiddenSize*FP32Bytes)+(PrefillBatch*TP1LocalVocab*FP32Bytes))+((0)+(0))+((0)+(0)) -> 656770882012 | AH13: =((TP8LocalVocab*HiddenSize*BF16Bytes)+(TotalLayers*(((HiddenSize)*(QLoraRank)*FP8Bytes+ROUNDUP((HiddenSize)/FP8Block,0)*ROUNDUP((QLoraRank)/FP8Block,0)*ScaleBytes)+((QLoraRank)*(TP8LocalHeads*HeadDim)*FP8Bytes+ROUNDUP((QLoraRank)/FP8Block,0)*ROUNDUP((TP8LocalHeads*HeadDim)/FP8Block,0)*ScaleBytes)+((HiddenSize)*(HeadDim)*FP8Bytes+ROUNDUP((HiddenSize)/FP8Block,0)*ROUNDUP((HeadDim)/FP8Block,0)*ScaleBytes)+TP8LocalHeads*HeadDim*OLoraRank*BF16Bytes+((TP8LocalOGroups*OLoraRank)*(HiddenSize)*FP8Bytes+ROUNDUP((TP8LocalOGroups*OLoraRank)/FP8Block,0)*ROUNDUP((HiddenSize)/FP8Block,0)*ScaleBytes)))+(0)+(0)+(0)+(ShortLayers*(((QLoraRank)*(TP8LocalIndexHeads*IndexHeadDim)*FP8Bytes+ROUNDUP((QLoraRank)/FP8Block,0)*ROUNDUP((TP8LocalIndexHeads*IndexHeadDim)/FP8Block,0)*ScaleBytes)+HiddenSize*TP8LocalIndexHeads*BF16Bytes))+(0)+(ShortLayers*(2*HiddenSize*(2*HeadDim)*FP32Bytes+ShortRatio*2*HeadDim*FP32Bytes+HeadDim*FP32Bytes))+(LongLayers*(2*HiddenSize*HeadDim*FP32Bytes+LongRatio*HeadDim*FP32Bytes+HeadDim*FP32Bytes))+(ShortLayers*(2*HiddenSize*(2*IndexHeadDim)*FP32Bytes+ShortRatio*2*IndexHeadDim*FP32Bytes+IndexHeadDim*FP32Bytes))+(TotalLayers*RoutedExperts*HiddenSize*BF16Bytes+(TotalLayers-ActiveHashLayers)*RoutedExperts*FP32Bytes+ActiveHashLayers*VocabSize*ActivatedExperts*INT32Bytes)+(TotalLayers*TP8LocalExperts*(3*HiddenSize*ExpertInter*FP4Bytes+3*HiddenSize*ExpertInter/FP4Block*ScaleBytes))+(TotalLayers*SharedExperts*(2*((HiddenSize)*(ExpertInter)*FP8Bytes+ROUNDUP((HiddenSize)/FP8Block,0)*ROUNDUP((ExpertInter)/FP8Block,0)*ScaleBytes)+((ExpertInter)*(HiddenSize)*FP8Bytes+ROUNDUP((ExpertInter)/FP8Block,0)*ROUNDUP((HiddenSize)/FP8Block,0)*ScaleBytes)))+((TotalLayers*2*(((2+HCSlots)*HCSlots)*HCSlots*HiddenSize+((2+HCSlots)*HCSlots)+3))*FP32Bytes+(HCSlots*HCSlots*HiddenSize+HCSlots+1)*FP32Bytes)+((TotalLayers*(2*HiddenSize+QLoraRank+HeadDim+TP8LocalHeads))*FP32Bytes+(HiddenSize)*FP32Bytes)+(0)+(TP8LocalVocab*HiddenSize*FP32Bytes)+(0)+(0))+(PrefillBatch*(HeadDim*BF16Bytes*(WindowLayers*WindowSize+ShortLayers*(WindowSize+INT(MaxContext/ShortRatio))+LongLayers*(WindowSize+INT(MaxContext/LongRatio)))+ShortLayers*INT(MaxContext/ShortRatio)*IndexHeadDim*BF16Bytes)+PrefillBatch*FP32Bytes*(ShortLayers*2*(2*ShortRatio)*(2*HeadDim)+LongLayers*2*LongRatio*HeadDim+ShortLayers*2*(2*ShortRatio)*(2*IndexHeadDim))) -> 29581867388 | AI13: =(0)+(PF_Rows*TotalLayers*2*(HiddenSize*QLoraRank+QLoraRank*TP8LocalHeads*HeadDim+HiddenSize*HeadDim+TP8LocalHeads*HeadDim*OLoraRank+TP8LocalOGroups*OLoraRank*HiddenSize))+(4*PrefillBatch*TP8KernelLocalHeads*HeadDim*(WindowLayers*PF_RawPairs))+(4*PrefillBatch*TP8KernelLocalHeads*HeadDim*(ShortLayers*(PF_RawPairs+PF_ShortPairs)))+(4*PrefillBatch*TP8KernelLocalHeads*HeadDim*(LongLayers*(PF_RawPairs+PF_LongPairs)))+(2*PF_Rows*ShortLayers*(QLoraRank*TP8LocalIndexHeads*IndexHeadDim+HiddenSize*TP8LocalIndexHeads))+(2*PrefillBatch*ShortLayers*TP8LocalIndexHeads*IndexHeadDim*PF_IndexPairs)+(PF_Rows*ShortLayers*8*HiddenSize*HeadDim)+(PF_Rows*LongLayers*4*HiddenSize*HeadDim)+(PF_Rows*ShortLayers*8*HiddenSize*IndexHeadDim)+(2*PF_Rows*TotalLayers*HiddenSize*RoutedExperts)+(PF_Rows*TotalLayers*(ActivatedExperts/TP8Size)*6*HiddenSize*ExpertInter)+(PF_Rows*TotalLayers*SharedExperts*6*HiddenSize*ExpertInter)+(TotalLayers*2*(2*PF_Rows*HCSlots*HiddenSize*((2+HCSlots)*HCSlots)+PF_Rows*(2*HCSlots*HiddenSize+1)+PF_Rows*HiddenSize*(2*HCSlots-1)+PF_Rows*HCSlots*HiddenSize*(2*HCSlots+1))+2*PF_Rows*HCSlots*HiddenSize*HCSlots+PF_Rows*(2*HCSlots*HiddenSize+1)+PF_Rows*HiddenSize*(2*HCSlots-1))+(PF_Rows*TotalLayers*2*(4*HiddenSize+1)+PF_Rows*(4*HiddenSize+1))+(0)+(2*PrefillBatch*HiddenSize*TP8LocalVocab)+(0)+(0) -> 55652568907776 | AJ13: =((PF_Rows*HiddenSize*BF16Bytes)+(PF_Rows*HiddenSize*BF16Bytes))+((TotalLayers*(((HiddenSize)*(QLoraRank)*FP8Bytes+ROUNDUP((HiddenSize)/FP8Block,0)*ROUNDUP((QLoraRank)/FP8Block,0)*ScaleBytes)+((QLoraRank)*(TP8LocalHeads*HeadDim)*FP8Bytes+ROUNDUP((QLoraRank)/FP8Block,0)*ROUNDUP((TP8LocalHeads*HeadDim)/FP8Block,0)*ScaleBytes)+((HiddenSize)*(HeadDim)*FP8Bytes+ROUNDUP((HiddenSize)/FP8Block,0)*ROUNDUP((HeadDim)/FP8Block,0)*ScaleBytes)+TP8LocalHeads*HeadDim*OLoraRank*BF16Bytes+((TP8LocalOGroups*OLoraRank)*(HiddenSize)*FP8Bytes+ROUNDUP((TP8LocalOGroups*OLoraRank)/FP8Block,0)*ROUNDUP((HiddenSize)/FP8Block,0)*ScaleBytes))+PF_Rows*TotalLayers*(2*HiddenSize*BF16Bytes+QLoraRank*BF16Bytes+TP8KernelLocalHeads*HeadDim*BF16Bytes+TP8LocalOGroups*OLoraRank*BF16Bytes))+(PF_Rows*TotalLayers*(QLoraRank+TP8KernelLocalHeads*HeadDim+HeadDim+TP8LocalOGroups*OLoraRank+HiddenSize)*BF16Bytes))+((PF_Rows*WindowLayers*TP8KernelLocalHeads*HeadDim*BF16Bytes+PrefillBatch*(WindowLayers*PF_RawPairs)*HeadDim*BF16Bytes)+(PF_Rows*WindowLayers*TP8KernelLocalHeads*HeadDim*BF16Bytes))+((PF_Rows*ShortLayers*TP8KernelLocalHeads*HeadDim*BF16Bytes+PrefillBatch*(ShortLayers*(PF_RawPairs+PF_ShortPairs))*HeadDim*BF16Bytes)+(PF_Rows*ShortLayers*TP8KernelLocalHeads*HeadDim*BF16Bytes))+((PF_Rows*LongLayers*TP8KernelLocalHeads*HeadDim*BF16Bytes+PrefillBatch*(LongLayers*(PF_RawPairs+PF_LongPairs))*HeadDim*BF16Bytes)+(PF_Rows*LongLayers*TP8KernelLocalHeads*HeadDim*BF16Bytes))+((ShortLayers*(((QLoraRank)*(TP8LocalIndexHeads*IndexHeadDim)*FP8Bytes+ROUNDUP((QLoraRank)/FP8Block,0)*ROUNDUP((TP8LocalIndexHeads*IndexHeadDim)/FP8Block,0)*ScaleBytes)+HiddenSize*TP8LocalIndexHeads*BF16Bytes)+PF_Rows*ShortLayers*(QLoraRank+HiddenSize)*BF16Bytes)+(PF_Rows*ShortLayers*TP8LocalIndexHeads*(IndexHeadDim+1)*BF16Bytes))+((PrefillBatch*ShortLayers*PF_IndexPairs*(IndexHeadDim*BF16Bytes+TP8LocalIndexHeads*BF16Bytes))+(PrefillBatch*ShortLayers*PF_IndexPairs*(TP8LocalIndexHeads*BF16Bytes+FP32Bytes)))+((ShortLayers*(2*HiddenSize*(2*HeadDim)*FP32Bytes+ShortRatio*2*HeadDim*FP32Bytes+HeadDim*FP32Bytes)+PF_Rows*ShortLayers*HiddenSize*FP32Bytes)+(PF_Rows*ShortLayers*4*HeadDim*FP32Bytes))+((LongLayers*(2*HiddenSize*HeadDim*FP32Bytes+LongRatio*HeadDim*FP32Bytes+HeadDim*FP32Bytes)+PF_Rows*LongLayers*HiddenSize*FP32Bytes)+(PF_Rows*LongLayers*2*HeadDim*FP32Bytes))+((ShortLayers*(2*HiddenSize*(2*IndexHeadDim)*FP32Bytes+ShortRatio*2*IndexHeadDim*FP32Bytes+IndexHeadDim*FP32Bytes)+PF_Rows*ShortLayers*HiddenSize*FP32Bytes)+(PF_Rows*ShortLayers*4*IndexHeadDim*FP32Bytes))+((TotalLayers*RoutedExperts*HiddenSize*BF16Bytes+(TotalLayers-ActiveHashLayers)*RoutedExperts*FP32Bytes+PF_Rows*TotalLayers*HiddenSize*BF16Bytes+PF_Rows*ActiveHashLayers*ActivatedExperts*INT32Bytes)+(PF_Rows*TotalLayers*RoutedExperts*FP32Bytes))+((TotalLayers*TP8LocalExperts*PF_ExpertActiveProbability*(3*HiddenSize*ExpertInter*FP4Bytes+3*HiddenSize*ExpertInter/FP4Block*ScaleBytes)+PF_Rows*TotalLayers*(ActivatedExperts/TP8Size)*HiddenSize*BF16Bytes)+(PF_Rows*TotalLayers*(ActivatedExperts/TP8Size)*HiddenSize*BF16Bytes))+((TotalLayers*SharedExperts*(2*((HiddenSize)*(ExpertInter)*FP8Bytes+ROUNDUP((HiddenSize)/FP8Block,0)*ROUNDUP((ExpertInter)/FP8Block,0)*ScaleBytes)+((ExpertInter)*(HiddenSize)*FP8Bytes+ROUNDUP((ExpertInter)/FP8Block,0)*ROUNDUP((HiddenSize)/FP8Block,0)*ScaleBytes))+PF_Rows*TotalLayers*SharedExperts*HiddenSize*BF16Bytes)+(PF_Rows*TotalLayers*SharedExperts*HiddenSize*BF16Bytes))+((TotalLayers*2*((2+HCSlots)*HCSlots*HCSlots*HiddenSize*FP32Bytes+((2+HCSlots)*HCSlots+3)*FP32Bytes)+PF_Rows*TotalLayers*4*HCSlots*HiddenSize*BF16Bytes+(HCSlots*HCSlots*HiddenSize+HCSlots+1)*FP32Bytes+PF_Rows*HCSlots*HiddenSize*BF16Bytes)+(PF_Rows*TotalLayers*4*HCSlots*HiddenSize*BF16Bytes+PF_Rows*HiddenSize*BF16Bytes))+((TotalLayers*(2*HiddenSize+QLoraRank+HeadDim+TP8LocalHeads)*FP32Bytes+HiddenSize*FP32Bytes+PF_Rows*TotalLayers*2*HiddenSize*BF16Bytes+PF_Rows*HiddenSize*BF16Bytes)+(PF_Rows*TotalLayers*2*HiddenSize*BF16Bytes+PF_Rows*HiddenSize*BF16Bytes))+((0)+(0))+((TP8LocalVocab*HiddenSize*FP32Bytes+PrefillBatch*HiddenSize*FP32Bytes)+(PrefillBatch*TP8LocalVocab*FP32Bytes))+((0)+(0))+((0)+(0)) -> 369337880060 | AK13: =(4*(TP1Size-1)/TP1Size*PF_Rows*HiddenSize*BF16Bytes)+(0)+(0)+(0)+(0)+(0)+(0)+(0)+(0)+(0)+(0)+(0)+(0)+(0)+(0)+(0)+(2*(TP1Size-1)*PrefillBatch*TP1LocalVocab*FP32Bytes)+(4*(TP1Size-1)/TP1Size*PF_Rows*HiddenSize*FP32Bytes*TotalLayers)+(4*(TP1Size-1)/TP1Size*PF_Rows*HiddenSize*FP32Bytes*TotalLayers) -> 0 | AL13: =(4*(TP8Size-1)/TP8Size*PF_Rows*HiddenSize*BF16Bytes)+(0)+(0)+(0)+(0)+(0)+(0)+(0)+(0)+(0)+(0)+(0)+(0)+(0)+(0)+(0)+(2*(TP8Size-1)*PrefillBatch*TP8LocalVocab*FP32Bytes)+(4*(TP8Size-1)/TP8Size*PF_Rows*HiddenSize*FP32Bytes*TotalLayers)+(4*(TP8Size-1)/TP8Size*PF_Rows*HiddenSize*FP32Bytes*TotalLayers) -> 40635322112
A14: Attention | B14: =TEXT(IF(ABS(AE14)>=1E12,AE14/1E12,IF(ABS(AE14)>=1E9,AE14/1E9,IF(ABS(AE14)>=1E6,AE14/1E6,IF(ABS(AE14)>=1E3,AE14/1E3,AE14)))),"#,##0.000")&IF((IF(ABS(AE14)>=1E12,"TB",IF(ABS(AE14)>=1E9,"GB",IF(ABS(AE14)>=1E6,"MB",IF(ABS(AE14)>=1E3,"KB","bytes")))))="",""," "&(IF(ABS(AE14)>=1E12,"TB",IF(ABS(AE14)>=1E9,"GB",IF(ABS(AE14)>=1E6,"MB",IF(ABS(AE14)>=1E3,"KB","bytes")))))) -> 7.451 GB | C14: =TEXT(IF(ABS(AF14)>=1E15,AF14/1E15,IF(ABS(AF14)>=1E12,AF14/1E12,IF(ABS(AF14)>=1E9,AF14/1E9,IF(ABS(AF14)>=1E6,AF14/1E6,AF14)))),"#,##0.000")&IF((IF(ABS(AF14)>=1E15,"PFLOPs",IF(ABS(AF14)>=1E12,"TFLOPs",IF(ABS(AF14)>=1E9,"GFLOPs",IF(ABS(AF14)>=1E6,"MFLOPs","flops")))))="",""," "&(IF(ABS(AF14)>=1E15,"PFLOPs",IF(ABS(AF14)>=1E12,"TFLOPs",IF(ABS(AF14)>=1E9,"GFLOPs",IF(ABS(AF14)>=1E6,"MFLOPs","flops")))))) -> 102.836 TFLOPs | D14: =TEXT(IF(ABS(AK14)>=1E12,AK14/1E12,IF(ABS(AK14)>=1E9,AK14/1E9,IF(ABS(AK14)>=1E6,AK14/1E6,IF(ABS(AK14)>=1E3,AK14/1E3,AK14)))),"#,##0.000")&IF((IF(ABS(AK14)>=1E12,"TB",IF(ABS(AK14)>=1E9,"GB",IF(ABS(AK14)>=1E6,"MB",IF(ABS(AK14)>=1E3,"KB","bytes")))))="",""," "&(IF(ABS(AK14)>=1E12,"TB",IF(ABS(AK14)>=1E9,"GB",IF(ABS(AK14)>=1E6,"MB",IF(ABS(AK14)>=1E3,"KB","bytes")))))) -> 0.000 B | E14: =TEXT(IF(ABS(AH14)>=1E12,AH14/1E12,IF(ABS(AH14)>=1E9,AH14/1E9,IF(ABS(AH14)>=1E6,AH14/1E6,IF(ABS(AH14)>=1E3,AH14/1E3,AH14)))),"#,##0.000")&IF((IF(ABS(AH14)>=1E12,"TB",IF(ABS(AH14)>=1E9,"GB",IF(ABS(AH14)>=1E6,"MB",IF(ABS(AH14)>=1E3,"KB","bytes")))))="",""," "&(IF(ABS(AH14)>=1E12,"TB",IF(ABS(AH14)>=1E9,"GB",IF(ABS(AH14)>=1E6,"MB",IF(ABS(AH14)>=1E3,"KB","bytes")))))) -> 2.238 GB | F14: =TEXT(IF(ABS(AI14)>=1E15,AI14/1E15,IF(ABS(AI14)>=1E12,AI14/1E12,IF(ABS(AI14)>=1E9,AI14/1E9,IF(ABS(AI14)>=1E6,AI14/1E6,AI14)))),"#,##0.000")&IF((IF(ABS(AI14)>=1E15,"PFLOPs",IF(ABS(AI14)>=1E12,"TFLOPs",IF(ABS(AI14)>=1E9,"GFLOPs",IF(ABS(AI14)>=1E6,"MFLOPs","flops")))))="",""," "&(IF(ABS(AI14)>=1E15,"PFLOPs",IF(ABS(AI14)>=1E12,"TFLOPs",IF(ABS(AI14)>=1E9,"GFLOPs",IF(ABS(AI14)>=1E6,"MFLOPs","flops")))))) -> 23.172 TFLOPs | G14: =TEXT(IF(ABS(AL14)>=1E12,AL14/1E12,IF(ABS(AL14)>=1E9,AL14/1E9,IF(ABS(AL14)>=1E6,AL14/1E6,IF(ABS(AL14)>=1E3,AL14/1E3,AL14)))),"#,##0.000")&IF((IF(ABS(AL14)>=1E12,"TB",IF(ABS(AL14)>=1E9,"GB",IF(ABS(AL14)>=1E6,"MB",IF(ABS(AL14)>=1E3,"KB","bytes")))))="",""," "&(IF(ABS(AL14)>=1E12,"TB",IF(ABS(AL14)>=1E9,"GB",IF(ABS(AL14)>=1E6,"MB",IF(ABS(AL14)>=1E3,"KB","bytes")))))) -> 20.200 GB | H14: FP8 / BF16 / FP32 | I14: BF16 / FP32 | J14: Window + short/long + Indexer；分类容量为 Attention 静态参数；缓存明细在下表。 | AE14: =(TotalLayers*(((HiddenSize)*(QLoraRank)*FP8Bytes+ROUNDUP((HiddenSize)/FP8Block,0)*ROUNDUP((QLoraRank)/FP8Block,0)*ScaleBytes)+((QLoraRank)*(TP1LocalHeads*HeadDim)*FP8Bytes+ROUNDUP((QLoraRank)/FP8Block,0)*ROUNDUP((TP1LocalHeads*HeadDim)/FP8Block,0)*ScaleBytes)+((HiddenSize)*(HeadDim)*FP8Bytes+ROUNDUP((HiddenSize)/FP8Block,0)*ROUNDUP((HeadDim)/FP8Block,0)*ScaleBytes)+TP1LocalHeads*HeadDim*OLoraRank*BF16Bytes+((TP1LocalOGroups*OLoraRank)*(HiddenSize)*FP8Bytes+ROUNDUP((TP1LocalOGroups*OLoraRank)/FP8Block,0)*ROUNDUP((HiddenSize)/FP8Block,0)*ScaleBytes)))+(0)+(0)+(0)+(ShortLayers*(((QLoraRank)*(TP1LocalIndexHeads*IndexHeadDim)*FP8Bytes+ROUNDUP((QLoraRank)/FP8Block,0)*ROUNDUP((TP1LocalIndexHeads*IndexHeadDim)/FP8Block,0)*ScaleBytes)+HiddenSize*TP1LocalIndexHeads*BF16Bytes))+(0)+(ShortLayers*(2*HiddenSize*(2*HeadDim)*FP32Bytes+ShortRatio*2*HeadDim*FP32Bytes+HeadDim*FP32Bytes))+(LongLayers*(2*HiddenSize*HeadDim*FP32Bytes+LongRatio*HeadDim*FP32Bytes+HeadDim*FP32Bytes))+(ShortLayers*(2*HiddenSize*(2*IndexHeadDim)*FP32Bytes+ShortRatio*2*IndexHeadDim*FP32Bytes+IndexHeadDim*FP32Bytes))+(0) -> 7451384960 | AF14: =(PF_Rows*TotalLayers*2*(HiddenSize*QLoraRank+QLoraRank*TP1LocalHeads*HeadDim+HiddenSize*HeadDim+TP1LocalHeads*HeadDim*OLoraRank+TP1LocalOGroups*OLoraRank*HiddenSize))+(4*PrefillBatch*TP1KernelLocalHeads*HeadDim*(WindowLayers*PF_RawPairs))+(4*PrefillBatch*TP1KernelLocalHeads*HeadDim*(ShortLayers*(PF_RawPairs+PF_ShortPairs)))+(4*PrefillBatch*TP1KernelLocalHeads*HeadDim*(LongLayers*(PF_RawPairs+PF_LongPairs)))+(2*PF_Rows*ShortLayers*(QLoraRank*TP1LocalIndexHeads*IndexHeadDim+HiddenSize*TP1LocalIndexHeads))+(2*PrefillBatch*ShortLayers*TP1LocalIndexHeads*IndexHeadDim*PF_IndexPairs)+(PF_Rows*ShortLayers*8*HiddenSize*HeadDim)+(PF_Rows*LongLayers*4*HiddenSize*HeadDim)+(PF_Rows*ShortLayers*8*HiddenSize*IndexHeadDim)+(0) -> 102836037746688 | AG14: =((TotalLayers*(((HiddenSize)*(QLoraRank)*FP8Bytes+ROUNDUP((HiddenSize)/FP8Block,0)*ROUNDUP((QLoraRank)/FP8Block,0)*ScaleBytes)+((QLoraRank)*(TP1LocalHeads*HeadDim)*FP8Bytes+ROUNDUP((QLoraRank)/FP8Block,0)*ROUNDUP((TP1LocalHeads*HeadDim)/FP8Block,0)*ScaleBytes)+((HiddenSize)*(HeadDim)*FP8Bytes+ROUNDUP((HiddenSize)/FP8Block,0)*ROUNDUP((HeadDim)/FP8Block,0)*ScaleBytes)+TP1LocalHeads*HeadDim*OLoraRank*BF16Bytes+((TP1LocalOGroups*OLoraRank)*(HiddenSize)*FP8Bytes+ROUNDUP((TP1LocalOGroups*OLoraRank)/FP8Block,0)*ROUNDUP((HiddenSize)/FP8Block,0)*ScaleBytes))+PF_Rows*TotalLayers*(2*HiddenSize*BF16Bytes+QLoraRank*BF16Bytes+TP1KernelLocalHeads*HeadDim*BF16Bytes+TP1LocalOGroups*OLoraRank*BF16Bytes))+(PF_Rows*TotalLayers*(QLoraRank+TP1KernelLocalHeads*HeadDim+HeadDim+TP1LocalOGroups*OLoraRank+HiddenSize)*BF16Bytes))+((PF_Rows*WindowLayers*TP1KernelLocalHeads*HeadDim*BF16Bytes+PrefillBatch*(WindowLayers*PF_RawPairs)*HeadDim*BF16Bytes)+(PF_Rows*WindowLayers*TP1KernelLocalHeads*HeadDim*BF16Bytes))+((PF_Rows*ShortLayers*TP1KernelLocalHeads*HeadDim*BF16Bytes+PrefillBatch*(ShortLayers*(PF_RawPairs+PF_ShortPairs))*HeadDim*BF16Bytes)+(PF_Rows*ShortLayers*TP1KernelLocalHeads*HeadDim*BF16Bytes))+((PF_Rows*LongLayers*TP1KernelLocalHeads*HeadDim*BF16Bytes+PrefillBatch*(LongLayers*(PF_RawPairs+PF_LongPairs))*HeadDim*BF16Bytes)+(PF_Rows*LongLayers*TP1KernelLocalHeads*HeadDim*BF16Bytes))+((ShortLayers*(((QLoraRank)*(TP1LocalIndexHeads*IndexHeadDim)*FP8Bytes+ROUNDUP((QLoraRank)/FP8Block,0)*ROUNDUP((TP1LocalIndexHeads*IndexHeadDim)/FP8Block,0)*ScaleBytes)+HiddenSize*TP1LocalIndexHeads*BF16Bytes)+PF_Rows*ShortLayers*(QLoraRank+HiddenSize)*BF16Bytes)+(PF_Rows*ShortLayers*TP1LocalIndexHeads*(IndexHeadDim+1)*BF16Bytes))+((PrefillBatch*ShortLayers*PF_IndexPairs*(IndexHeadDim*BF16Bytes+TP1LocalIndexHeads*BF16Bytes))+(PrefillBatch*ShortLayers*PF_IndexPairs*(TP1LocalIndexHeads*BF16Bytes+FP32Bytes)))+((ShortLayers*(2*HiddenSize*(2*HeadDim)*FP32Bytes+ShortRatio*2*HeadDim*FP32Bytes+HeadDim*FP32Bytes)+PF_Rows*ShortLayers*HiddenSize*FP32Bytes)+(PF_Rows*ShortLayers*4*HeadDim*FP32Bytes))+((LongLayers*(2*HiddenSize*HeadDim*FP32Bytes+LongRatio*HeadDim*FP32Bytes+HeadDim*FP32Bytes)+PF_Rows*LongLayers*HiddenSize*FP32Bytes)+(PF_Rows*LongLayers*2*HeadDim*FP32Bytes))+((ShortLayers*(2*HiddenSize*(2*IndexHeadDim)*FP32Bytes+ShortRatio*2*IndexHeadDim*FP32Bytes+IndexHeadDim*FP32Bytes)+PF_Rows*ShortLayers*HiddenSize*FP32Bytes)+(PF_Rows*ShortLayers*4*IndexHeadDim*FP32Bytes))+((0)+(0)) -> 358037814400 | AH14: =(TotalLayers*(((HiddenSize)*(QLoraRank)*FP8Bytes+ROUNDUP((HiddenSize)/FP8Block,0)*ROUNDUP((QLoraRank)/FP8Block,0)*ScaleBytes)+((QLoraRank)*(TP8LocalHeads*HeadDim)*FP8Bytes+ROUNDUP((QLoraRank)/FP8Block,0)*ROUNDUP((TP8LocalHeads*HeadDim)/FP8Block,0)*ScaleBytes)+((HiddenSize)*(HeadDim)*FP8Bytes+ROUNDUP((HiddenSize)/FP8Block,0)*ROUNDUP((HeadDim)/FP8Block,0)*ScaleBytes)+TP8LocalHeads*HeadDim*OLoraRank*BF16Bytes+((TP8LocalOGroups*OLoraRank)*(HiddenSize)*FP8Bytes+ROUNDUP((TP8LocalOGroups*OLoraRank)/FP8Block,0)*ROUNDUP((HiddenSize)/FP8Block,0)*ScaleBytes)))+(0)+(0)+(0)+(ShortLayers*(((QLoraRank)*(TP8LocalIndexHeads*IndexHeadDim)*FP8Bytes+ROUNDUP((QLoraRank)/FP8Block,0)*ROUNDUP((TP8LocalIndexHeads*IndexHeadDim)/FP8Block,0)*ScaleBytes)+HiddenSize*TP8LocalIndexHeads*BF16Bytes))+(0)+(ShortLayers*(2*HiddenSize*(2*HeadDim)*FP32Bytes+ShortRatio*2*HeadDim*FP32Bytes+HeadDim*FP32Bytes))+(LongLayers*(2*HiddenSize*HeadDim*FP32Bytes+LongRatio*HeadDim*FP32Bytes+HeadDim*FP32Bytes))+(ShortLayers*(2*HiddenSize*(2*IndexHeadDim)*FP32Bytes+ShortRatio*2*IndexHeadDim*FP32Bytes+IndexHeadDim*FP32Bytes))+(0) -> 2237504960 | AI14: =(PF_Rows*TotalLayers*2*(HiddenSize*QLoraRank+QLoraRank*TP8LocalHeads*HeadDim+HiddenSize*HeadDim+TP8LocalHeads*HeadDim*OLoraRank+TP8LocalOGroups*OLoraRank*HiddenSize))+(4*PrefillBatch*TP8KernelLocalHeads*HeadDim*(WindowLayers*PF_RawPairs))+(4*PrefillBatch*TP8KernelLocalHeads*HeadDim*(ShortLayers*(PF_RawPairs+PF_ShortPairs)))+(4*PrefillBatch*TP8KernelLocalHeads*HeadDim*(LongLayers*(PF_RawPairs+PF_LongPairs)))+(2*PF_Rows*ShortLayers*(QLoraRank*TP8LocalIndexHeads*IndexHeadDim+HiddenSize*TP8LocalIndexHeads))+(2*PrefillBatch*ShortLayers*TP8LocalIndexHeads*IndexHeadDim*PF_IndexPairs)+(PF_Rows*ShortLayers*8*HiddenSize*HeadDim)+(PF_Rows*LongLayers*4*HiddenSize*HeadDim)+(PF_Rows*ShortLayers*8*HiddenSize*IndexHeadDim)+(0) -> 23172382457856 | AJ14: =((TotalLayers*(((HiddenSize)*(QLoraRank)*FP8Bytes+ROUNDUP((HiddenSize)/FP8Block,0)*ROUNDUP((QLoraRank)/FP8Block,0)*ScaleBytes)+((QLoraRank)*(TP8LocalHeads*HeadDim)*FP8Bytes+ROUNDUP((QLoraRank)/FP8Block,0)*ROUNDUP((TP8LocalHeads*HeadDim)/FP8Block,0)*ScaleBytes)+((HiddenSize)*(HeadDim)*FP8Bytes+ROUNDUP((HiddenSize)/FP8Block,0)*ROUNDUP((HeadDim)/FP8Block,0)*ScaleBytes)+TP8LocalHeads*HeadDim*OLoraRank*BF16Bytes+((TP8LocalOGroups*OLoraRank)*(HiddenSize)*FP8Bytes+ROUNDUP((TP8LocalOGroups*OLoraRank)/FP8Block,0)*ROUNDUP((HiddenSize)/FP8Block,0)*ScaleBytes))+PF_Rows*TotalLayers*(2*HiddenSize*BF16Bytes+QLoraRank*BF16Bytes+TP8KernelLocalHeads*HeadDim*BF16Bytes+TP8LocalOGroups*OLoraRank*BF16Bytes))+(PF_Rows*TotalLayers*(QLoraRank+TP8KernelLocalHeads*HeadDim+HeadDim+TP8LocalOGroups*OLoraRank+HiddenSize)*BF16Bytes))+((PF_Rows*WindowLayers*TP8KernelLocalHeads*HeadDim*BF16Bytes+PrefillBatch*(WindowLayers*PF_RawPairs)*HeadDim*BF16Bytes)+(PF_Rows*WindowLayers*TP8KernelLocalHeads*HeadDim*BF16Bytes))+((PF_Rows*ShortLayers*TP8KernelLocalHeads*HeadDim*BF16Bytes+PrefillBatch*(ShortLayers*(PF_RawPairs+PF_ShortPairs))*HeadDim*BF16Bytes)+(PF_Rows*ShortLayers*TP8KernelLocalHeads*HeadDim*BF16Bytes))+((PF_Rows*LongLayers*TP8KernelLocalHeads*HeadDim*BF16Bytes+PrefillBatch*(LongLayers*(PF_RawPairs+PF_LongPairs))*HeadDim*BF16Bytes)+(PF_Rows*LongLayers*TP8KernelLocalHeads*HeadDim*BF16Bytes))+((ShortLayers*(((QLoraRank)*(TP8LocalIndexHeads*IndexHeadDim)*FP8Bytes+ROUNDUP((QLoraRank)/FP8Block,0)*ROUNDUP((TP8LocalIndexHeads*IndexHeadDim)/FP8Block,0)*ScaleBytes)+HiddenSize*TP8LocalIndexHeads*BF16Bytes)+PF_Rows*ShortLayers*(QLoraRank+HiddenSize)*BF16Bytes)+(PF_Rows*ShortLayers*TP8LocalIndexHeads*(IndexHeadDim+1)*BF16Bytes))+((PrefillBatch*ShortLayers*PF_IndexPairs*(IndexHeadDim*BF16Bytes+TP8LocalIndexHeads*BF16Bytes))+(PrefillBatch*ShortLayers*PF_IndexPairs*(TP8LocalIndexHeads*BF16Bytes+FP32Bytes)))+((ShortLayers*(2*HiddenSize*(2*HeadDim)*FP32Bytes+ShortRatio*2*HeadDim*FP32Bytes+HeadDim*FP32Bytes)+PF_Rows*ShortLayers*HiddenSize*FP32Bytes)+(PF_Rows*ShortLayers*4*HeadDim*FP32Bytes))+((LongLayers*(2*HiddenSize*HeadDim*FP32Bytes+LongRatio*HeadDim*FP32Bytes+HeadDim*FP32Bytes)+PF_Rows*LongLayers*HiddenSize*FP32Bytes)+(PF_Rows*LongLayers*2*HeadDim*FP32Bytes))+((ShortLayers*(2*HiddenSize*(2*IndexHeadDim)*FP32Bytes+ShortRatio*2*IndexHeadDim*FP32Bytes+IndexHeadDim*FP32Bytes)+PF_Rows*ShortLayers*HiddenSize*FP32Bytes)+(PF_Rows*ShortLayers*4*IndexHeadDim*FP32Bytes))+((0)+(0)) -> 231531806144 | AK14: =(0)+(0)+(0)+(0)+(0)+(0)+(0)+(0)+(0)+(4*(TP1Size-1)/TP1Size*PF_Rows*HiddenSize*FP32Bytes*TotalLayers) -> 0 | AL14: =(0)+(0)+(0)+(0)+(0)+(0)+(0)+(0)+(0)+(4*(TP8Size-1)/TP8Size*PF_Rows*HiddenSize*FP32Bytes*TotalLayers) -> 20199768064
A15: MoE | B15: =TEXT(IF(ABS(AE15)>=1E12,AE15/1E12,IF(ABS(AE15)>=1E9,AE15/1E9,IF(ABS(AE15)>=1E6,AE15/1E6,IF(ABS(AE15)>=1E3,AE15/1E3,AE15)))),"#,##0.000")&IF((IF(ABS(AE15)>=1E12,"TB",IF(ABS(AE15)>=1E9,"GB",IF(ABS(AE15)>=1E6,"MB",IF(ABS(AE15)>=1E3,"KB","bytes")))))="",""," "&(IF(ABS(AE15)>=1E12,"TB",IF(ABS(AE15)>=1E9,"GB",IF(ABS(AE15)>=1E6,"MB",IF(ABS(AE15)>=1E3,"KB","bytes")))))) -> 148.351 GB | C15: =TEXT(IF(ABS(AF15)>=1E15,AF15/1E15,IF(ABS(AF15)>=1E12,AF15/1E12,IF(ABS(AF15)>=1E9,AF15/1E9,IF(ABS(AF15)>=1E6,AF15/1E6,AF15)))),"#,##0.000")&IF((IF(ABS(AF15)>=1E15,"PFLOPs",IF(ABS(AF15)>=1E12,"TFLOPs",IF(ABS(AF15)>=1E9,"GFLOPs",IF(ABS(AF15)>=1E6,"MFLOPs","flops")))))="",""," "&(IF(ABS(AF15)>=1E15,"PFLOPs",IF(ABS(AF15)>=1E12,"TFLOPs",IF(ABS(AF15)>=1E9,"GFLOPs",IF(ABS(AF15)>=1E6,"MFLOPs","flops")))))) -> 124.846 TFLOPs | D15: =TEXT(IF(ABS(AK15)>=1E12,AK15/1E12,IF(ABS(AK15)>=1E9,AK15/1E9,IF(ABS(AK15)>=1E6,AK15/1E6,IF(ABS(AK15)>=1E3,AK15/1E3,AK15)))),"#,##0.000")&IF((IF(ABS(AK15)>=1E12,"TB",IF(ABS(AK15)>=1E9,"GB",IF(ABS(AK15)>=1E6,"MB",IF(ABS(AK15)>=1E3,"KB","bytes")))))="",""," "&(IF(ABS(AK15)>=1E12,"TB",IF(ABS(AK15)>=1E9,"GB",IF(ABS(AK15)>=1E6,"MB",IF(ABS(AK15)>=1E3,"KB","bytes")))))) -> 0.000 B | E15: =TEXT(IF(ABS(AH15)>=1E12,AH15/1E12,IF(ABS(AH15)>=1E9,AH15/1E9,IF(ABS(AH15)>=1E6,AH15/1E6,IF(ABS(AH15)>=1E3,AH15/1E3,AH15)))),"#,##0.000")&IF((IF(ABS(AH15)>=1E12,"TB",IF(ABS(AH15)>=1E9,"GB",IF(ABS(AH15)>=1E6,"MB",IF(ABS(AH15)>=1E3,"KB","bytes")))))="",""," "&(IF(ABS(AH15)>=1E12,"TB",IF(ABS(AH15)>=1E9,"GB",IF(ABS(AH15)>=1E6,"MB",IF(ABS(AH15)>=1E3,"KB","bytes")))))) -> 19.578 GB | F15: =TEXT(IF(ABS(AI15)>=1E15,AI15/1E15,IF(ABS(AI15)>=1E12,AI15/1E12,IF(ABS(AI15)>=1E9,AI15/1E9,IF(ABS(AI15)>=1E6,AI15/1E6,AI15)))),"#,##0.000")&IF((IF(ABS(AI15)>=1E15,"PFLOPs",IF(ABS(AI15)>=1E12,"TFLOPs",IF(ABS(AI15)>=1E9,"GFLOPs",IF(ABS(AI15)>=1E6,"MFLOPs","flops")))))="",""," "&(IF(ABS(AI15)>=1E15,"PFLOPs",IF(ABS(AI15)>=1E12,"TFLOPs",IF(ABS(AI15)>=1E9,"GFLOPs",IF(ABS(AI15)>=1E6,"MFLOPs","flops")))))) -> 31.766 TFLOPs | G15: =TEXT(IF(ABS(AL15)>=1E12,AL15/1E12,IF(ABS(AL15)>=1E9,AL15/1E9,IF(ABS(AL15)>=1E6,AL15/1E6,IF(ABS(AL15)>=1E3,AL15/1E3,AL15)))),"#,##0.000")&IF((IF(ABS(AL15)>=1E12,"TB",IF(ABS(AL15)>=1E9,"GB",IF(ABS(AL15)>=1E6,"MB",IF(ABS(AL15)>=1E3,"KB","bytes")))))="",""," "&(IF(ABS(AL15)>=1E12,"TB",IF(ABS(AL15)>=1E9,"GB",IF(ABS(AL15)>=1E6,"MB",IF(ABS(AL15)>=1E3,"KB","bytes")))))) -> 20.200 GB | H15: FP4 / FP8 / BF16 / FP32 / INT32 | I15: BF16 / FP32 / INT32 | J15: All active layers；路由专家、共享专家和 Router。 | AE15: =(TotalLayers*RoutedExperts*HiddenSize*BF16Bytes+(TotalLayers-ActiveHashLayers)*RoutedExperts*FP32Bytes+ActiveHashLayers*VocabSize*ActivatedExperts*INT32Bytes)+(TotalLayers*TP1LocalExperts*(3*HiddenSize*ExpertInter*FP4Bytes+3*HiddenSize*ExpertInter/FP4Block*ScaleBytes))+(TotalLayers*SharedExperts*(2*((HiddenSize)*(ExpertInter)*FP8Bytes+ROUNDUP((HiddenSize)/FP8Block,0)*ROUNDUP((ExpertInter)/FP8Block,0)*ScaleBytes)+((ExpertInter)*(HiddenSize)*FP8Bytes+ROUNDUP((ExpertInter)/FP8Block,0)*ROUNDUP((HiddenSize)/FP8Block,0)*ScaleBytes)))+(0) -> 148351461888 | AF15: =(2*PF_Rows*TotalLayers*HiddenSize*RoutedExperts)+(PF_Rows*TotalLayers*(ActivatedExperts/TP1Size)*6*HiddenSize*ExpertInter)+(PF_Rows*TotalLayers*SharedExperts*6*HiddenSize*ExpertInter)+(0) -> 124846109360128 | AG15: =((TotalLayers*RoutedExperts*HiddenSize*BF16Bytes+(TotalLayers-ActiveHashLayers)*RoutedExperts*FP32Bytes+PF_Rows*TotalLayers*HiddenSize*BF16Bytes+PF_Rows*ActiveHashLayers*ActivatedExperts*INT32Bytes)+(PF_Rows*TotalLayers*RoutedExperts*FP32Bytes))+((TotalLayers*TP1LocalExperts*PF_ExpertActiveProbability*(3*HiddenSize*ExpertInter*FP4Bytes+3*HiddenSize*ExpertInter/FP4Block*ScaleBytes)+PF_Rows*TotalLayers*(ActivatedExperts/TP1Size)*HiddenSize*BF16Bytes)+(PF_Rows*TotalLayers*(ActivatedExperts/TP1Size)*HiddenSize*BF16Bytes))+((TotalLayers*SharedExperts*(2*((HiddenSize)*(ExpertInter)*FP8Bytes+ROUNDUP((HiddenSize)/FP8Block,0)*ROUNDUP((ExpertInter)/FP8Block,0)*ScaleBytes)+((ExpertInter)*(HiddenSize)*FP8Bytes+ROUNDUP((ExpertInter)/FP8Block,0)*ROUNDUP((HiddenSize)/FP8Block,0)*ScaleBytes))+PF_Rows*TotalLayers*SharedExperts*HiddenSize*BF16Bytes)+(PF_Rows*TotalLayers*SharedExperts*HiddenSize*BF16Bytes))+((0)+(0)) -> 191988670976 | AH15: =(TotalLayers*RoutedExperts*HiddenSize*BF16Bytes+(TotalLayers-ActiveHashLayers)*RoutedExperts*FP32Bytes+ActiveHashLayers*VocabSize*ActivatedExperts*INT32Bytes)+(TotalLayers*TP8LocalExperts*(3*HiddenSize*ExpertInter*FP4Bytes+3*HiddenSize*ExpertInter/FP4Block*ScaleBytes))+(TotalLayers*SharedExperts*(2*((HiddenSize)*(ExpertInter)*FP8Bytes+ROUNDUP((HiddenSize)/FP8Block,0)*ROUNDUP((ExpertInter)/FP8Block,0)*ScaleBytes)+((ExpertInter)*(HiddenSize)*FP8Bytes+ROUNDUP((ExpertInter)/FP8Block,0)*ROUNDUP((HiddenSize)/FP8Block,0)*ScaleBytes)))+(0) -> 19577940480 | AI15: =(2*PF_Rows*TotalLayers*HiddenSize*RoutedExperts)+(PF_Rows*TotalLayers*(ActivatedExperts/TP8Size)*6*HiddenSize*ExpertInter)+(PF_Rows*TotalLayers*SharedExperts*6*HiddenSize*ExpertInter)+(0) -> 31765578121216 | AJ15: =((TotalLayers*RoutedExperts*HiddenSize*BF16Bytes+(TotalLayers-ActiveHashLayers)*RoutedExperts*FP32Bytes+PF_Rows*TotalLayers*HiddenSize*BF16Bytes+PF_Rows*ActiveHashLayers*ActivatedExperts*INT32Bytes)+(PF_Rows*TotalLayers*RoutedExperts*FP32Bytes))+((TotalLayers*TP8LocalExperts*PF_ExpertActiveProbability*(3*HiddenSize*ExpertInter*FP4Bytes+3*HiddenSize*ExpertInter/FP4Block*ScaleBytes)+PF_Rows*TotalLayers*(ActivatedExperts/TP8Size)*HiddenSize*BF16Bytes)+(PF_Rows*TotalLayers*(ActivatedExperts/TP8Size)*HiddenSize*BF16Bytes))+((TotalLayers*SharedExperts*(2*((HiddenSize)*(ExpertInter)*FP8Bytes+ROUNDUP((HiddenSize)/FP8Block,0)*ROUNDUP((ExpertInter)/FP8Block,0)*ScaleBytes)+((ExpertInter)*(HiddenSize)*FP8Bytes+ROUNDUP((ExpertInter)/FP8Block,0)*ROUNDUP((HiddenSize)/FP8Block,0)*ScaleBytes))+PF_Rows*TotalLayers*SharedExperts*HiddenSize*BF16Bytes)+(PF_Rows*TotalLayers*SharedExperts*HiddenSize*BF16Bytes))+((0)+(0)) -> 32915497472 | AK15: =(0)+(0)+(0)+(4*(TP1Size-1)/TP1Size*PF_Rows*HiddenSize*FP32Bytes*TotalLayers) -> 0 | AL15: =(0)+(0)+(0)+(4*(TP8Size-1)/TP8Size*PF_Rows*HiddenSize*FP32Bytes*TotalLayers) -> 20199768064
A16: Embedding | B16: =TEXT(IF(ABS(AE16)>=1E12,AE16/1E12,IF(ABS(AE16)>=1E9,AE16/1E9,IF(ABS(AE16)>=1E6,AE16/1E6,IF(ABS(AE16)>=1E3,AE16/1E3,AE16)))),"#,##0.000")&IF((IF(ABS(AE16)>=1E12,"TB",IF(ABS(AE16)>=1E9,"GB",IF(ABS(AE16)>=1E6,"MB",IF(ABS(AE16)>=1E3,"KB","bytes")))))="",""," "&(IF(ABS(AE16)>=1E12,"TB",IF(ABS(AE16)>=1E9,"GB",IF(ABS(AE16)>=1E6,"MB",IF(ABS(AE16)>=1E3,"KB","bytes")))))) -> 1.059 GB | C16: =TEXT(IF(ABS(AF16)>=1E15,AF16/1E15,IF(ABS(AF16)>=1E12,AF16/1E12,IF(ABS(AF16)>=1E9,AF16/1E9,IF(ABS(AF16)>=1E6,AF16/1E6,AF16)))),"#,##0.000")&IF((IF(ABS(AF16)>=1E15,"PFLOPs",IF(ABS(AF16)>=1E12,"TFLOPs",IF(ABS(AF16)>=1E9,"GFLOPs",IF(ABS(AF16)>=1E6,"MFLOPs","flops")))))="",""," "&(IF(ABS(AF16)>=1E15,"PFLOPs",IF(ABS(AF16)>=1E12,"TFLOPs",IF(ABS(AF16)>=1E9,"GFLOPs",IF(ABS(AF16)>=1E6,"MFLOPs","flops")))))) -> 0.000 FLOPs | D16: =TEXT(IF(ABS(AK16)>=1E12,AK16/1E12,IF(ABS(AK16)>=1E9,AK16/1E9,IF(ABS(AK16)>=1E6,AK16/1E6,IF(ABS(AK16)>=1E3,AK16/1E3,AK16)))),"#,##0.000")&IF((IF(ABS(AK16)>=1E12,"TB",IF(ABS(AK16)>=1E9,"GB",IF(ABS(AK16)>=1E6,"MB",IF(ABS(AK16)>=1E3,"KB","bytes")))))="",""," "&(IF(ABS(AK16)>=1E12,"TB",IF(ABS(AK16)>=1E9,"GB",IF(ABS(AK16)>=1E6,"MB",IF(ABS(AK16)>=1E3,"KB","bytes")))))) -> 0.000 B | E16: =TEXT(IF(ABS(AH16)>=1E12,AH16/1E12,IF(ABS(AH16)>=1E9,AH16/1E9,IF(ABS(AH16)>=1E6,AH16/1E6,IF(ABS(AH16)>=1E3,AH16/1E3,AH16)))),"#,##0.000")&IF((IF(ABS(AH16)>=1E12,"TB",IF(ABS(AH16)>=1E9,"GB",IF(ABS(AH16)>=1E6,"MB",IF(ABS(AH16)>=1E3,"KB","bytes")))))="",""," "&(IF(ABS(AH16)>=1E12,"TB",IF(ABS(AH16)>=1E9,"GB",IF(ABS(AH16)>=1E6,"MB",IF(ABS(AH16)>=1E3,"KB","bytes")))))) -> 132.383 MB | F16: =TEXT(IF(ABS(AI16)>=1E15,AI16/1E15,IF(ABS(AI16)>=1E12,AI16/1E12,IF(ABS(AI16)>=1E9,AI16/1E9,IF(ABS(AI16)>=1E6,AI16/1E6,AI16)))),"#,##0.000")&IF((IF(ABS(AI16)>=1E15,"PFLOPs",IF(ABS(AI16)>=1E12,"TFLOPs",IF(ABS(AI16)>=1E9,"GFLOPs",IF(ABS(AI16)>=1E6,"MFLOPs","flops")))))="",""," "&(IF(ABS(AI16)>=1E15,"PFLOPs",IF(ABS(AI16)>=1E12,"TFLOPs",IF(ABS(AI16)>=1E9,"GFLOPs",IF(ABS(AI16)>=1E6,"MFLOPs","flops")))))) -> 0.000 FLOPs | G16: =TEXT(IF(ABS(AL16)>=1E12,AL16/1E12,IF(ABS(AL16)>=1E9,AL16/1E9,IF(ABS(AL16)>=1E6,AL16/1E6,IF(ABS(AL16)>=1E3,AL16/1E3,AL16)))),"#,##0.000")&IF((IF(ABS(AL16)>=1E12,"TB",IF(ABS(AL16)>=1E9,"GB",IF(ABS(AL16)>=1E6,"MB",IF(ABS(AL16)>=1E3,"KB","bytes")))))="",""," "&(IF(ABS(AL16)>=1E12,"TB",IF(ABS(AL16)>=1E9,"GB",IF(ABS(AL16)>=1E6,"MB",IF(ABS(AL16)>=1E3,"KB","bytes")))))) -> 234.881 MB | H16: BF16 | I16: BF16 hidden / residual | J16: Input embedding；词表维度按 TP 分片。 | AE16: =(TP1LocalVocab*HiddenSize*BF16Bytes) -> 1059061760 | AF16: =(0) -> 0 | AG16: =((PF_Rows*HiddenSize*BF16Bytes)+(PF_Rows*HiddenSize*BF16Bytes)) -> 134217728 | AH16: =(TP8LocalVocab*HiddenSize*BF16Bytes) -> 132382720 | AI16: =(0) -> 0 | AJ16: =((PF_Rows*HiddenSize*BF16Bytes)+(PF_Rows*HiddenSize*BF16Bytes)) -> 134217728 | AK16: =(4*(TP1Size-1)/TP1Size*PF_Rows*HiddenSize*BF16Bytes) -> 0 | AL16: =(4*(TP8Size-1)/TP8Size*PF_Rows*HiddenSize*BF16Bytes) -> 234881024
A17: LM Head | B17: =TEXT(IF(ABS(AE17)>=1E12,AE17/1E12,IF(ABS(AE17)>=1E9,AE17/1E9,IF(ABS(AE17)>=1E6,AE17/1E6,IF(ABS(AE17)>=1E3,AE17/1E3,AE17)))),"#,##0.000")&IF((IF(ABS(AE17)>=1E12,"TB",IF(ABS(AE17)>=1E9,"GB",IF(ABS(AE17)>=1E6,"MB",IF(ABS(AE17)>=1E3,"KB","bytes")))))="",""," "&(IF(ABS(AE17)>=1E12,"TB",IF(ABS(AE17)>=1E9,"GB",IF(ABS(AE17)>=1E6,"MB",IF(ABS(AE17)>=1E3,"KB","bytes")))))) -> 2.118 GB | C17: =TEXT(IF(ABS(AF17)>=1E15,AF17/1E15,IF(ABS(AF17)>=1E12,AF17/1E12,IF(ABS(AF17)>=1E9,AF17/1E9,IF(ABS(AF17)>=1E6,AF17/1E6,AF17)))),"#,##0.000")&IF((IF(ABS(AF17)>=1E15,"PFLOPs",IF(ABS(AF17)>=1E12,"TFLOPs",IF(ABS(AF17)>=1E9,"GFLOPs",IF(ABS(AF17)>=1E6,"MFLOPs","flops")))))="",""," "&(IF(ABS(AF17)>=1E15,"PFLOPs",IF(ABS(AF17)>=1E12,"TFLOPs",IF(ABS(AF17)>=1E9,"GFLOPs",IF(ABS(AF17)>=1E6,"MFLOPs","flops")))))) -> 1.059 GFLOPs | D17: =TEXT(IF(ABS(AK17)>=1E12,AK17/1E12,IF(ABS(AK17)>=1E9,AK17/1E9,IF(ABS(AK17)>=1E6,AK17/1E6,IF(ABS(AK17)>=1E3,AK17/1E3,AK17)))),"#,##0.000")&IF((IF(ABS(AK17)>=1E12,"TB",IF(ABS(AK17)>=1E9,"GB",IF(ABS(AK17)>=1E6,"MB",IF(ABS(AK17)>=1E3,"KB","bytes")))))="",""," "&(IF(ABS(AK17)>=1E12,"TB",IF(ABS(AK17)>=1E9,"GB",IF(ABS(AK17)>=1E6,"MB",IF(ABS(AK17)>=1E3,"KB","bytes")))))) -> 0.000 B | E17: =TEXT(IF(ABS(AH17)>=1E12,AH17/1E12,IF(ABS(AH17)>=1E9,AH17/1E9,IF(ABS(AH17)>=1E6,AH17/1E6,IF(ABS(AH17)>=1E3,AH17/1E3,AH17)))),"#,##0.000")&IF((IF(ABS(AH17)>=1E12,"TB",IF(ABS(AH17)>=1E9,"GB",IF(ABS(AH17)>=1E6,"MB",IF(ABS(AH17)>=1E3,"KB","bytes")))))="",""," "&(IF(ABS(AH17)>=1E12,"TB",IF(ABS(AH17)>=1E9,"GB",IF(ABS(AH17)>=1E6,"MB",IF(ABS(AH17)>=1E3,"KB","bytes")))))) -> 264.765 MB | F17: =TEXT(IF(ABS(AI17)>=1E15,AI17/1E15,IF(ABS(AI17)>=1E12,AI17/1E12,IF(ABS(AI17)>=1E9,AI17/1E9,IF(ABS(AI17)>=1E6,AI17/1E6,AI17)))),"#,##0.000")&IF((IF(ABS(AI17)>=1E15,"PFLOPs",IF(ABS(AI17)>=1E12,"TFLOPs",IF(ABS(AI17)>=1E9,"GFLOPs",IF(ABS(AI17)>=1E6,"MFLOPs","flops")))))="",""," "&(IF(ABS(AI17)>=1E15,"PFLOPs",IF(ABS(AI17)>=1E12,"TFLOPs",IF(ABS(AI17)>=1E9,"GFLOPs",IF(ABS(AI17)>=1E6,"MFLOPs","flops")))))) -> 132.383 MFLOPs | G17: =TEXT(IF(ABS(AL17)>=1E12,AL17/1E12,IF(ABS(AL17)>=1E9,AL17/1E9,IF(ABS(AL17)>=1E6,AL17/1E6,IF(ABS(AL17)>=1E3,AL17/1E3,AL17)))),"#,##0.000")&IF((IF(ABS(AL17)>=1E12,"TB",IF(ABS(AL17)>=1E9,"GB",IF(ABS(AL17)>=1E6,"MB",IF(ABS(AL17)>=1E3,"KB","bytes")))))="",""," "&(IF(ABS(AL17)>=1E12,"TB",IF(ABS(AL17)>=1E9,"GB",IF(ABS(AL17)>=1E6,"MB",IF(ABS(AL17)>=1E3,"KB","bytes")))))) -> 904.960 KB | H17: FP32 | I17: FP32 logits | J17: Model tail；词表维度按 TP 分片；Prefill 只计算最后一个 token 的 logits。 | AE17: =(TP1LocalVocab*HiddenSize*FP32Bytes) -> 2118123520 | AF17: =(2*PrefillBatch*HiddenSize*TP1LocalVocab) -> 1059061760 | AG17: =((TP1LocalVocab*HiddenSize*FP32Bytes+PrefillBatch*HiddenSize*FP32Bytes)+(PrefillBatch*TP1LocalVocab*FP32Bytes)) -> 2118657024 | AH17: =(TP8LocalVocab*HiddenSize*FP32Bytes) -> 264765440 | AI17: =(2*PrefillBatch*HiddenSize*TP8LocalVocab) -> 132382720 | AJ17: =((TP8LocalVocab*HiddenSize*FP32Bytes+PrefillBatch*HiddenSize*FP32Bytes)+(PrefillBatch*TP8LocalVocab*FP32Bytes)) -> 264846464 | AK17: =(2*(TP1Size-1)*PrefillBatch*TP1LocalVocab*FP32Bytes) -> 0 | AL17: =(2*(TP8Size-1)*PrefillBatch*TP8LocalVocab*FP32Bytes) -> 904960
A18: Norm | B18: =TEXT(IF(ABS(AE18)>=1E12,AE18/1E12,IF(ABS(AE18)>=1E9,AE18/1E9,IF(ABS(AE18)>=1E6,AE18/1E6,IF(ABS(AE18)>=1E3,AE18/1E3,AE18)))),"#,##0.000")&IF((IF(ABS(AE18)>=1E12,"TB",IF(ABS(AE18)>=1E9,"GB",IF(ABS(AE18)>=1E6,"MB",IF(ABS(AE18)>=1E3,"KB","bytes")))))="",""," "&(IF(ABS(AE18)>=1E12,"TB",IF(ABS(AE18)>=1E9,"GB",IF(ABS(AE18)>=1E6,"MB",IF(ABS(AE18)>=1E3,"KB","bytes")))))) -> 1.701 MB | C18: =TEXT(IF(ABS(AF18)>=1E15,AF18/1E15,IF(ABS(AF18)>=1E12,AF18/1E12,IF(ABS(AF18)>=1E9,AF18/1E9,IF(ABS(AF18)>=1E6,AF18/1E6,AF18)))),"#,##0.000")&IF((IF(ABS(AF18)>=1E15,"PFLOPs",IF(ABS(AF18)>=1E12,"TFLOPs",IF(ABS(AF18)>=1E9,"GFLOPs",IF(ABS(AF18)>=1E6,"MFLOPs","flops")))))="",""," "&(IF(ABS(AF18)>=1E15,"PFLOPs",IF(ABS(AF18)>=1E12,"TFLOPs",IF(ABS(AF18)>=1E9,"GFLOPs",IF(ABS(AF18)>=1E6,"MFLOPs","flops")))))) -> 11.678 GFLOPs | D18: =TEXT(IF(ABS(AK18)>=1E12,AK18/1E12,IF(ABS(AK18)>=1E9,AK18/1E9,IF(ABS(AK18)>=1E6,AK18/1E6,IF(ABS(AK18)>=1E3,AK18/1E3,AK18)))),"#,##0.000")&IF((IF(ABS(AK18)>=1E12,"TB",IF(ABS(AK18)>=1E9,"GB",IF(ABS(AK18)>=1E6,"MB",IF(ABS(AK18)>=1E3,"KB","bytes")))))="",""," "&(IF(ABS(AK18)>=1E12,"TB",IF(ABS(AK18)>=1E9,"GB",IF(ABS(AK18)>=1E6,"MB",IF(ABS(AK18)>=1E3,"KB","bytes")))))) -> 0.000 B | E18: =TEXT(IF(ABS(AH18)>=1E12,AH18/1E12,IF(ABS(AH18)>=1E9,AH18/1E9,IF(ABS(AH18)>=1E6,AH18/1E6,IF(ABS(AH18)>=1E3,AH18/1E3,AH18)))),"#,##0.000")&IF((IF(ABS(AH18)>=1E12,"TB",IF(ABS(AH18)>=1E9,"GB",IF(ABS(AH18)>=1E6,"MB",IF(ABS(AH18)>=1E3,"KB","bytes")))))="",""," "&(IF(ABS(AH18)>=1E12,"TB",IF(ABS(AH18)>=1E9,"GB",IF(ABS(AH18)>=1E6,"MB",IF(ABS(AH18)>=1E3,"KB","bytes")))))) -> 1.691 MB | F18: =TEXT(IF(ABS(AI18)>=1E15,AI18/1E15,IF(ABS(AI18)>=1E12,AI18/1E12,IF(ABS(AI18)>=1E9,AI18/1E9,IF(ABS(AI18)>=1E6,AI18/1E6,AI18)))),"#,##0.000")&IF((IF(ABS(AI18)>=1E15,"PFLOPs",IF(ABS(AI18)>=1E12,"TFLOPs",IF(ABS(AI18)>=1E9,"GFLOPs",IF(ABS(AI18)>=1E6,"MFLOPs","flops")))))="",""," "&(IF(ABS(AI18)>=1E15,"PFLOPs",IF(ABS(AI18)>=1E12,"TFLOPs",IF(ABS(AI18)>=1E9,"GFLOPs",IF(ABS(AI18)>=1E6,"MFLOPs","flops")))))) -> 11.678 GFLOPs | G18: =TEXT(IF(ABS(AL18)>=1E12,AL18/1E12,IF(ABS(AL18)>=1E9,AL18/1E9,IF(ABS(AL18)>=1E6,AL18/1E6,IF(ABS(AL18)>=1E3,AL18/1E3,AL18)))),"#,##0.000")&IF((IF(ABS(AL18)>=1E12,"TB",IF(ABS(AL18)>=1E9,"GB",IF(ABS(AL18)>=1E6,"MB",IF(ABS(AL18)>=1E3,"KB","bytes")))))="",""," "&(IF(ABS(AL18)>=1E12,"TB",IF(ABS(AL18)>=1E9,"GB",IF(ABS(AL18)>=1E6,"MB",IF(ABS(AL18)>=1E3,"KB","bytes")))))) -> 0.000 B | H18: FP32 | I18: BF16 -> FP32 -> BF16 | J18: Block norms + final norm；含注意力 Sink 向量的参数容量。 | AE18: =((TotalLayers*(2*HiddenSize+QLoraRank+HeadDim+TP1LocalHeads))*FP32Bytes+(HiddenSize)*FP32Bytes) -> 1700608 | AF18: =(PF_Rows*TotalLayers*2*(4*HiddenSize+1)+PF_Rows*(4*HiddenSize+1)) -> 11677655040 | AG18: =((TotalLayers*(2*HiddenSize+QLoraRank+HeadDim+TP1LocalHeads)*FP32Bytes+HiddenSize*FP32Bytes+PF_Rows*TotalLayers*2*HiddenSize*BF16Bytes+PF_Rows*HiddenSize*BF16Bytes)+(PF_Rows*TotalLayers*2*HiddenSize*BF16Bytes+PF_Rows*HiddenSize*BF16Bytes)) -> 11678642944 | AH18: =((TotalLayers*(2*HiddenSize+QLoraRank+HeadDim+TP8LocalHeads))*FP32Bytes+(HiddenSize)*FP32Bytes) -> 1690976 | AI18: =(PF_Rows*TotalLayers*2*(4*HiddenSize+1)+PF_Rows*(4*HiddenSize+1)) -> 11677655040 | AJ18: =((TotalLayers*(2*HiddenSize+QLoraRank+HeadDim+TP8LocalHeads)*FP32Bytes+HiddenSize*FP32Bytes+PF_Rows*TotalLayers*2*HiddenSize*BF16Bytes+PF_Rows*HiddenSize*BF16Bytes)+(PF_Rows*TotalLayers*2*HiddenSize*BF16Bytes+PF_Rows*HiddenSize*BF16Bytes)) -> 11678633312 | AK18: =(0) -> 0 | AL18: =(0) -> 0
A19: HC | B19: =TEXT(IF(ABS(AE19)>=1E12,AE19/1E12,IF(ABS(AE19)>=1E9,AE19/1E9,IF(ABS(AE19)>=1E6,AE19/1E6,IF(ABS(AE19)>=1E3,AE19/1E3,AE19)))),"#,##0.000")&IF((IF(ABS(AE19)>=1E12,"TB",IF(ABS(AE19)>=1E9,"GB",IF(ABS(AE19)>=1E6,"MB",IF(ABS(AE19)>=1E3,"KB","bytes")))))="",""," "&(IF(ABS(AE19)>=1E12,"TB",IF(ABS(AE19)>=1E9,"GB",IF(ABS(AE19)>=1E6,"MB",IF(ABS(AE19)>=1E3,"KB","bytes")))))) -> 135.538 MB | C19: =TEXT(IF(ABS(AF19)>=1E15,AF19/1E15,IF(ABS(AF19)>=1E12,AF19/1E12,IF(ABS(AF19)>=1E9,AF19/1E9,IF(ABS(AF19)>=1E6,AF19/1E6,AF19)))),"#,##0.000")&IF((IF(ABS(AF19)>=1E15,"PFLOPs",IF(ABS(AF19)>=1E12,"TFLOPs",IF(ABS(AF19)>=1E9,"GFLOPs",IF(ABS(AF19)>=1E6,"MFLOPs","flops")))))="",""," "&(IF(ABS(AF19)>=1E15,"PFLOPs",IF(ABS(AF19)>=1E12,"TFLOPs",IF(ABS(AF19)>=1E9,"GFLOPs",IF(ABS(AF19)>=1E6,"MFLOPs","flops")))))) -> 702.798 GFLOPs | D19: =TEXT(IF(ABS(AK19)>=1E12,AK19/1E12,IF(ABS(AK19)>=1E9,AK19/1E9,IF(ABS(AK19)>=1E6,AK19/1E6,IF(ABS(AK19)>=1E3,AK19/1E3,AK19)))),"#,##0.000")&IF((IF(ABS(AK19)>=1E12,"TB",IF(ABS(AK19)>=1E9,"GB",IF(ABS(AK19)>=1E6,"MB",IF(ABS(AK19)>=1E3,"KB","bytes")))))="",""," "&(IF(ABS(AK19)>=1E12,"TB",IF(ABS(AK19)>=1E9,"GB",IF(ABS(AK19)>=1E6,"MB",IF(ABS(AK19)>=1E3,"KB","bytes")))))) -> 0.000 B | E19: =TEXT(IF(ABS(AH19)>=1E12,AH19/1E12,IF(ABS(AH19)>=1E9,AH19/1E9,IF(ABS(AH19)>=1E6,AH19/1E6,IF(ABS(AH19)>=1E3,AH19/1E3,AH19)))),"#,##0.000")&IF((IF(ABS(AH19)>=1E12,"TB",IF(ABS(AH19)>=1E9,"GB",IF(ABS(AH19)>=1E6,"MB",IF(ABS(AH19)>=1E3,"KB","bytes")))))="",""," "&(IF(ABS(AH19)>=1E12,"TB",IF(ABS(AH19)>=1E9,"GB",IF(ABS(AH19)>=1E6,"MB",IF(ABS(AH19)>=1E3,"KB","bytes")))))) -> 135.538 MB | F19: =TEXT(IF(ABS(AI19)>=1E15,AI19/1E15,IF(ABS(AI19)>=1E12,AI19/1E12,IF(ABS(AI19)>=1E9,AI19/1E9,IF(ABS(AI19)>=1E6,AI19/1E6,AI19)))),"#,##0.000")&IF((IF(ABS(AI19)>=1E15,"PFLOPs",IF(ABS(AI19)>=1E12,"TFLOPs",IF(ABS(AI19)>=1E9,"GFLOPs",IF(ABS(AI19)>=1E6,"MFLOPs","flops")))))="",""," "&(IF(ABS(AI19)>=1E15,"PFLOPs",IF(ABS(AI19)>=1E12,"TFLOPs",IF(ABS(AI19)>=1E9,"GFLOPs",IF(ABS(AI19)>=1E6,"MFLOPs","flops")))))) -> 702.798 GFLOPs | G19: =TEXT(IF(ABS(AL19)>=1E12,AL19/1E12,IF(ABS(AL19)>=1E9,AL19/1E9,IF(ABS(AL19)>=1E6,AL19/1E6,IF(ABS(AL19)>=1E3,AL19/1E3,AL19)))),"#,##0.000")&IF((IF(ABS(AL19)>=1E12,"TB",IF(ABS(AL19)>=1E9,"GB",IF(ABS(AL19)>=1E6,"MB",IF(ABS(AL19)>=1E3,"KB","bytes")))))="",""," "&(IF(ABS(AL19)>=1E12,"TB",IF(ABS(AL19)>=1E9,"GB",IF(ABS(AL19)>=1E6,"MB",IF(ABS(AL19)>=1E3,"KB","bytes")))))) -> 0.000 B | H19: FP32 | I19: FP32 mixing + BF16 hidden/residual | J19: Block HC + tail HC head；含 block HC 和模型尾部 HC head。 | AE19: =((TotalLayers*2*(((2+HCSlots)*HCSlots)*HCSlots*HiddenSize+((2+HCSlots)*HCSlots)+3))*FP32Bytes+(HCSlots*HCSlots*HiddenSize+HCSlots+1)*FP32Bytes) -> 135537756 | AF19: =(TotalLayers*2*(2*PF_Rows*HCSlots*HiddenSize*((2+HCSlots)*HCSlots)+PF_Rows*(2*HCSlots*HiddenSize+1)+PF_Rows*HiddenSize*(2*HCSlots-1)+PF_Rows*HCSlots*HiddenSize*(2*HCSlots+1))+2*PF_Rows*HCSlots*HiddenSize*HCSlots+PF_Rows*(2*HCSlots*HiddenSize+1)+PF_Rows*HiddenSize*(2*HCSlots-1)) -> 702798290944 | AG19: =((TotalLayers*2*((2+HCSlots)*HCSlots*HCSlots*HiddenSize*FP32Bytes+((2+HCSlots)*HCSlots+3)*FP32Bytes)+PF_Rows*TotalLayers*4*HCSlots*HiddenSize*BF16Bytes+(HCSlots*HCSlots*HiddenSize+HCSlots+1)*FP32Bytes+PF_Rows*HCSlots*HiddenSize*BF16Bytes)+(PF_Rows*TotalLayers*4*HCSlots*HiddenSize*BF16Bytes+PF_Rows*HiddenSize*BF16Bytes)) -> 92812878940 | AH19: =((TotalLayers*2*(((2+HCSlots)*HCSlots)*HCSlots*HiddenSize+((2+HCSlots)*HCSlots)+3))*FP32Bytes+(HCSlots*HCSlots*HiddenSize+HCSlots+1)*FP32Bytes) -> 135537756 | AI19: =(TotalLayers*2*(2*PF_Rows*HCSlots*HiddenSize*((2+HCSlots)*HCSlots)+PF_Rows*(2*HCSlots*HiddenSize+1)+PF_Rows*HiddenSize*(2*HCSlots-1)+PF_Rows*HCSlots*HiddenSize*(2*HCSlots+1))+2*PF_Rows*HCSlots*HiddenSize*HCSlots+PF_Rows*(2*HCSlots*HiddenSize+1)+PF_Rows*HiddenSize*(2*HCSlots-1)) -> 702798290944 | AJ19: =((TotalLayers*2*((2+HCSlots)*HCSlots*HCSlots*HiddenSize*FP32Bytes+((2+HCSlots)*HCSlots+3)*FP32Bytes)+PF_Rows*TotalLayers*4*HCSlots*HiddenSize*BF16Bytes+(HCSlots*HCSlots*HiddenSize+HCSlots+1)*FP32Bytes+PF_Rows*HCSlots*HiddenSize*BF16Bytes)+(PF_Rows*TotalLayers*4*HCSlots*HiddenSize*BF16Bytes+PF_Rows*HiddenSize*BF16Bytes)) -> 92812878940 | AK19: =(0) -> 0 | AL19: =(0) -> 0
